Workbook

Sheet 用例总览
A1: CallMate / TonoCard App 测试用例库
A2: 覆盖 iOS、Android、App+MCU、App+服务端、三端通话、OTA恢复、异常性能安全；以当前首页、BLE v2与现行服务契约为准。2026-08-13：初始化改为资料表单+五屏引导，见 App公共 COM-049~060。
A4: 工作表 | B4: 用例总数 | C4: P0 | D4: P1 | E4: P2 | F4: P3 | H4: 执行组合 | I4: 最低配置 | J4: 主要用途
A5: App公共 | B5: =COUNTA(App公共!$A$4:$A$63) | C5: =COUNTIF(App公共!$E$4:$E$63,"P0") | D5: =COUNTIF(App公共!$E$4:$E$63,"P1") | E5: =COUNTIF(App公共!$E$4:$E$63,"P2") | F5: =COUNTIF(App公共!$E$4:$E$63,"P3") | H5: App 单端 | I5: iOS Simulator / Android Emulator | J5: UI、导航、本地数据、基础权限
A6: iOS专项 | B6: =COUNTA(iOS专项!$A$4:$A$33) | C6: =COUNTIF(iOS专项!$E$4:$E$33,"P0") | D6: =COUNTIF(iOS专项!$E$4:$E$33,"P1") | E6: =COUNTIF(iOS专项!$E$4:$E$33,"P2") | F6: =COUNTIF(iOS专项!$E$4:$E$33,"P3") | H6: App + MCU | I6: 1台手机 + 1块525或52J | J6: BLE v2、绑定、HFP/SCO、设备管理
A7: Android专项 | B7: =COUNTA(Android专项!$A$4:$A$33) | C7: =COUNTIF(Android专项!$E$4:$E$33,"P0") | D7: =COUNTIF(Android专项!$E$4:$E$33,"P1") | E7: =COUNTIF(Android专项!$E$4:$E$33,"P2") | F7: =COUNTIF(Android专项!$E$4:$E$33,"P3") | H7: 三端通话 | I7: 来电方 + 被测手机 + MCU + dev服务 | J7: 真实来电/外呼、双向音频、摘要
A8: App_MCU | B8: =COUNTA(App_MCU!$A$4:$A$55) | C8: =COUNTIF(App_MCU!$E$4:$E$55,"P0") | D8: =COUNTIF(App_MCU!$E$4:$E$55,"P1") | E8: =COUNTIF(App_MCU!$E$4:$E$55,"P2") | F8: =COUNTIF(App_MCU!$E$4:$E$55,"P3") | H8: 双手机 | I8: 2台授权手机 + MCU + 来电方 | J8: owner、ring_local、撤权与身份隔离
A9: App_服务端 | B9: =COUNTA(App_服务端!$A$4:$A$48) | C9: =COUNTIF(App_服务端!$E$4:$E$48,"P0") | D9: =COUNTIF(App_服务端!$E$4:$E$48,"P1") | E9: =COUNTIF(App_服务端!$E$4:$E$48,"P2") | F9: =COUNTIF(App_服务端!$E$4:$E$48,"P3") | H9: OTA | I9: 525与52J各1块 + 可控供电 | J9: 丢块、中断、重启确认、回滚、ANCS恢复
A10: 三端通话 | B10: =COUNTA(三端通话!$A$4:$A$65) | C10: =COUNTIF(三端通话!$E$4:$E$65,"P0") | D10: =COUNTIF(三端通话!$E$4:$E$65,"P1") | E10: =COUNTIF(三端通话!$E$4:$E$65,"P2") | F10: =COUNTIF(三端通话!$E$4:$E$65,"P3") | H10: 生产冒烟 | I10: 候选App + 候选固件 + prod服务 | J10: P0发布阻断验证
A11: OTA恢复 | B11: =COUNTA(OTA恢复!$A$4:$A$33) | C11: =COUNTIF(OTA恢复!$E$4:$E$33,"P0") | D11: =COUNTIF(OTA恢复!$E$4:$E$33,"P1") | E11: =COUNTIF(OTA恢复!$E$4:$E$33,"P2") | F11: =COUNTIF(OTA恢复!$E$4:$E$33,"P3")
A12: 异常性能安全 | B12: =COUNTA(异常性能安全!$A$4:$A$34) | C12: =COUNTIF(异常性能安全!$E$4:$E$34,"P0") | D12: =COUNTIF(异常性能安全!$E$4:$E$34,"P1") | E12: =COUNTIF(异常性能安全!$E$4:$E$34,"P2") | F12: =COUNTIF(异常性能安全!$E$4:$E$34,"P3")
A13: 合计 | B13: =SUM(B5:B12) | C13: =SUM(C5:C12) | D13: =SUM(D5:D12) | E13: =SUM(E5:E12) | F13: =SUM(F5:F12)
A15: 执行注意：MCU日志行首 [tick] 是32.768kHz连续时钟；Δ秒=(tick2-tick1)/32768。出现SFBL/SiFli启动banner表示重启，禁止跨启动周期相减。

Sheet P0发布冒烟
A1: CallMate / TonoCard · P0 发布冒烟套件
A2: 共 96 条代表性发布阻断用例；完整 P0 请在各模块工作表按优先级筛选。2026-08-13：增补初始化引导 COM-049/051/052/053/055/056/060。
A3: 顺序 | B3: 用例 ID | C3: 来源工作表 | D3: 二级模块 | E3: 用例标题 | F3: 平台 | G3: 组合层级 | H3: 前置条件 | I3: 操作步骤 | J3: 通过标准
A4: 1 | B4: COM-001 | C4: App公共 | D4: 启动与合规 | E4: 全新安装首次启动显示用户协议与隐私政策 | F4: iOS/Android | G4: App 单端 | H4: 卸载 App 后重新安装，确保无历史数据 | I4: 启动 App；观察首屏；尝试点击弹窗外区域 | J4: App：显示 TonoCard 合规弹窗；背景不可操作；同意、不同意、用户协议、隐私政策入口可见且可点击 MCU：不涉及 服务端：不涉及
A5: 2 | B5: COM-005 | C5: App公共 | D5: 启动与合规 | E5: 同意协议后状态持久化 | F5: iOS/Android | G5: App 单端 | H5: 首次启动合规弹窗已显示 | I5: 点击同意；完成一次页面跳转；杀进程后重新启动 | J5: App：合规弹窗不重复出现；进入绑定/恢复后的正确状态；不得跳过必要权限与绑定流程 MCU：不涉及 服务端：不涉及
A6: 3 | B6: COM-010 | C6: App公共 | D6: 权限 | E6: 麦克风未授权时首页给出可执行引导 | F6: iOS/Android | G6: App 单端 | H6: 系统麦克风权限为未决定或拒绝 | I6: 进入首页；查看权限卡；点击下一步/设置入口 | J6: App：明确说明麦克风用途；未授权不假装可用；授权成功后权限卡实时更新 MCU：不涉及 服务端：不涉及
A7: 4 | B7: COM-013 | C7: App公共 | D7: 状态恢复 | E7: 已完成绑定与引导时冷启动恢复首页 | F7: iOS/Android | G7: App 单端 | H7: 本地保存有效设备与已完成引导标记 | I7: 杀进程；重新启动；等待启动恢复完成 | J7: App：直接进入当前 TonoCard 首页；不回到扫描或引导页；连接状态按真实链路更新 MCU：不涉及 服务端：不涉及
A8: 5 | B8: COM-016 | C8: App公共 | D8: 首页 | E8: 当前首页布局与核心入口完整 | F8: iOS/Android | G8: App 单端 | H8: 使用 UI 测试模式或已完成绑定引导 | I8: 进入首页；检查标题、连接状态、接管模式、权限卡、个人中心与 AI 分身按钮 | J8: App：显示 TonoCard 首页；不存在旧三 Tab；核心入口可见且无遮挡；AI 分身为右下悬浮按钮 MCU：不涉及 服务端：不涉及
A9: 6 | B9: COM-017 | C9: App公共 | D9: 首页 | E9: 设备未连接状态展示准确 | F9: iOS/Android | G9: App 单端 | H9: 已绑定但 MCU 不在范围内或关机 | I9: 启动 App；观察顶部设备状态与接管模式区域 | J9: App：显示未连接/可重连语义；不得显示已连接、电量或正在工作；需要设备的操作给出明确反馈 MCU：不涉及 服务端：不涉及
A10: 7 | B10: COM-019 | C10: App公共 | D10: 接管模式 | E10: 切换为不接管模式 | F10: iOS/Android | G10: App 单端 | H10: 已进入首页且设备连接可用 | I10: 点击不接管；离开首页再返回 | J10: App：选中态正确；说明文案表示不由 AI 代接；页面返回后保持选择 MCU：不涉及 服务端：不涉及
A11: 8 | B11: COM-020 | C11: App公共 | D11: 接管模式 | E11: 切换为陌生来电模式 | F11: iOS/Android | G11: App 单端 | H11: 已进入首页且设备连接可用 | I11: 点击陌生来电；观察说明；重启 App | J11: App：陌生来电模式选中并持久化；说明为持续接听陌生来电；不误显示全接管 MCU：不涉及 服务端：不涉及
A12: 9 | B12: IOS-001 | C12: iOS专项 | D12: 蓝牙权限 | E12: 首次扫描触发系统蓝牙权限 | F12: iOS | G12: 平台专项 | H12: 全新安装并同意协议，蓝牙权限未决定 | I12: 进入绑定扫描；处理系统蓝牙权限弹窗 | J12: App：系统框只出现一次；允许后开始扫描；拒绝后停止扫描并显示系统设置引导 MCU：不涉及 服务端：不涉及
A13: 10 | B13: IOS-002 | C13: iOS专项 | D13: 绑定恢复 | E13: CoreBluetooth 后台恢复已保存设备 | F13: iOS | G13: 平台专项 | H13: 已绑定 MCU，允许蓝牙后台模式 | I13: 杀进程；让 MCU 重连或产生可唤醒事件；重新前台 App | J13: App：复用同一 BLE 对象图恢复连接；不创建第二条连接；首页状态与真实设备一致 MCU：不涉及 服务端：不涉及
A14: 11 | B14: IOS-004 | C14: iOS专项 | D14: ANCS | E14: 用户同意后发起 ANCS 开启 | F14: iOS | G14: 平台专项 | H14: 已连接 MCU，尚未记录 ANCS 用户同意 | I14: 点击首页来电通知邀请；处理系统通知共享弹窗 | J14: App：记录按当前 device UID 隔离；显示正在开启；不在没有端到端证据时直接宣称成功 MCU：不涉及 服务端：不涉及
A15: 12 | B15: IOS-005 | C15: iOS专项 | D15: ANCS | E15: ANCS transport subscribed 不等于投递成功 | F15: iOS | G15: 平台专项 | H15: MCU 上报 ancs_transport_status=subscribed，但无真实 ANCS packet | I15: 进入首页与设备页；等待稳定窗 | J15: App：不得仅据 subscribed 显示已授权成功；设备页仍可执行端到端检查 MCU：不涉及 服务端：不涉及
... A99: 96 | B99: COM-060 | C99: App公共 | D99: 初始化引导 | E99: Android凭证未就绪不闪错屏 | F99: Android | G99: App + MCU + 服务端 | H99: BLE已连、token稍后落地 | I99: 尽快进向导观察首屏 | J99: 等token再建连；无错误闪屏；不假完成

Sheet App公共
A1: CallMate / TonoCard 测试用例 · App 公共功能
A2: 共 60 条；按优先级、平台、组合层级和执行结果筛选。MCU 日志行首为 32.768 kHz raw tick，重启前后禁止直接相减。2026-08-13：增补初始化引导 COM-049~060（表单+五屏），修订 COM-014。
A3: 用例 ID | B3: 一级模块 | C3: 二级模块 | D3: 用例标题 | E3: 优先级 | F3: 平台 | G3: 组合层级 | H3: 自动化建议 | I3: 前置条件 | J3: 测试数据 | K3: 操作步骤 | L3: App 预期结果 | M3: MCU 预期结果 | N3: 服务端预期结果 | O3: 证据/日志 | P3: 执行结果 | Q3: 缺陷 ID | R3: 依据/备注
A4: COM-001 | B4: App 公共功能 | C4: 启动与合规 | D4: 全新安装首次启动显示用户协议与隐私政策 | E4: P0 | F4: iOS/Android | G4: App 单端 | H4: UI 自动化/人工 | I4: 卸载 App 后重新安装，确保无历史数据 | J4: 使用当前测试版本与独立测试账号；执行前清理上一条用例残留状态 | K4: 启动 App；观察首屏；尝试点击弹窗外区域 | L4: 显示 TonoCard 合规弹窗；背景不可操作；同意、不同意、用户协议、隐私政策入口可见且可点击 | M4: 不涉及 | N4: 不涉及 | O4: 操作截图、App 控制台日志 | P4: 未执行
A5: COM-002 | B5: App 公共功能 | C5: 启动与合规 | D5: 打开用户协议正文并返回 | E5: P1 | F5: iOS/Android | G5: App 单端 | H5: UI 自动化/人工 | I5: 首次启动合规弹窗已显示 | J5: 使用当前测试版本与独立测试账号；执行前清理上一条用例残留状态 | K5: 点击《TonoCard 用户协议》；滚动到末尾；返回 | L5: 展示本地协议全文，无空白页或加载错误；返回后仍停留在合规弹窗 | M5: 不涉及 | N5: 不涉及 | O5: 操作截图、App 控制台日志 | P5: 未执行
A6: COM-003 | B6: App 公共功能 | C6: 启动与合规 | D6: 打开隐私政策正文并返回 | E6: P1 | F6: iOS/Android | G6: App 单端 | H6: UI 自动化/人工 | I6: 首次启动合规弹窗已显示 | J6: 使用当前测试版本与独立测试账号；执行前清理上一条用例残留状态 | K6: 点击《TonoCard 隐私政策》；滚动到末尾；返回 | L6: 展示本地隐私政策全文；中英文资源与当前语言一致；返回路径正确 | M6: 不涉及 | N6: 不涉及 | O6: 操作截图、App 控制台日志 | P6: 未执行
A7: COM-004 | B7: App 公共功能 | C7: 启动与合规 | D7: 点击不同意退出 App | E7: P1 | F7: iOS/Android | G7: App 单端 | H7: UI 自动化/人工 | I7: 首次启动合规弹窗已显示 | J7: 使用当前测试版本与独立测试账号；执行前清理上一条用例残留状态 | K7: 点击不同意；再次从桌面启动 App | L7: 本次进程退出或停止进入服务；再次启动仍要求用户确认，不得偷偷写入已同意状态 | M7: 不涉及 | N7: 不涉及 | O7: 操作截图、App 控制台日志 | P7: 未执行
A8: COM-005 | B8: App 公共功能 | C8: 启动与合规 | D8: 同意协议后状态持久化 | E8: P0 | F8: iOS/Android | G8: App 单端 | H8: UI 自动化/人工 | I8: 首次启动合规弹窗已显示 | J8: 使用当前测试版本与独立测试账号；执行前清理上一条用例残留状态 | K8: 点击同意；完成一次页面跳转；杀进程后重新启动 | L8: 合规弹窗不重复出现；进入绑定/恢复后的正确状态；不得跳过必要权限与绑定流程 | M8: 不涉及 | N8: 不涉及 | O8: 操作截图、App 控制台日志 | P8: 未执行
A9: COM-006 | B9: App 公共功能 | C9: 启动与合规 | D9: 版本升级保留合规同意状态 | E9: P2 | F9: iOS/Android | G9: App 单端 | H9: UI 自动化/人工 | I9: 旧版本已同意协议并完成绑定 | J9: 使用当前测试版本与独立测试账号；执行前清理上一条用例残留状态 | K9: 覆盖安装候选版本；启动 App | L9: 不重复弹旧版协议；若协议版本未变化则直接恢复原状态；本地数据仍在 | M9: 不涉及 | N9: 不涉及 | O9: 操作截图、App 控制台日志 | P9: 未执行
A10: COM-007 | B10: App 公共功能 | C10: 语言 | D10: 系统中文时首次默认中文 | E10: P1 | F10: iOS/Android | G10: App 单端 | H10: UI 自动化/人工 | I10: 系统语言为简体中文，App 无显式语言偏好 | J10: 使用当前测试版本与独立测试账号；执行前清理上一条用例残留状态 | K10: 全新安装并启动；查看合规、绑定、首页文案 | L10: 界面默认中文；关键按钮、权限说明和错误提示无英文残留 | M10: 不涉及 | N10: 不涉及 | O10: 操作截图、App 控制台日志 | P10: 未执行
A11: COM-008 | B11: App 公共功能 | C11: 语言 | D11: 系统英文时首次默认英文 | E11: P1 | F11: iOS/Android | G11: App 单端 | H11: UI 自动化/人工 | I11: 系统语言为英文，App 无显式语言偏好 | J11: 使用当前测试版本与独立测试账号；执行前清理上一条用例残留状态 | K11: 全新安装并启动；查看合规、绑定、首页文案 | L11: 界面默认英文；布局未因英文长度截断关键操作 | M11: 不涉及 | N11: 不涉及 | O11: 操作截图、App 控制台日志 | P11: 未执行
A12: COM-009 | B12: App 公共功能 | C12: 语言 | D12: 设置中切换中英文并持久化 | E12: P1 | F12: iOS/Android | G12: App 单端 | H12: UI 自动化/人工 | I12: 已进入首页 | J12: 使用当前测试版本与独立测试账号；执行前清理上一条用例残留状态 | K12: 进入个人中心/设置；切换语言；返回首页；杀进程重启 | L12: 当前页面与后续页面即时切换；重启后保留用户显式选择；通话记录数据不受影响 | M12: 不涉及 | N12: 不涉及 | O12: 操作截图、App 控制台日志 | P12: 未执行
A13: COM-010 | B13: App 公共功能 | C13: 权限 | D13: 麦克风未授权时首页给出可执行引导 | E13: P0 | F13: iOS/Android | G13: App 单端 | H13: UI 自动化/人工 | I13: 系统麦克风权限为未决定或拒绝 | J13: 使用当前测试版本与独立测试账号；执行前清理上一条用例残留状态 | K13: 进入首页；查看权限卡；点击下一步/设置入口 | L13: 明确说明麦克风用途；未授权不假装可用；授权成功后权限卡实时更新 | M13: 不涉及 | N13: 不涉及 | O13: 操作截图、App 控制台日志 | P13: 未执行
A14: COM-011 | B14: App 公共功能 | C14: 权限 | D14: 通知未授权时首页给出可执行引导 | E14: P1 | F14: iOS/Android | G14: App 单端 | H14: UI 自动化/人工 | I14: 系统通知权限为未决定或拒绝 | J14: 使用当前测试版本与独立测试账号；执行前清理上一条用例残留状态 | K14: 进入首页；查看权限卡；点击继续并处理系统弹窗 | L14: 通知用途说明准确；允许后状态更新；拒绝后提供系统设置恢复入口 | M14: 不涉及 | N14: 不涉及 | O14: 操作截图、App 控制台日志 | P14: 未执行
A15: COM-012 | B15: App 公共功能 | C15: 权限 | D15: 用户拒绝权限后再次进入不死循环弹系统框 | E15: P1 | F15: iOS/Android | G15: App 单端 | H15: UI 自动化/人工 | I15: 已拒绝麦克风或通知权限 | J15: 使用当前测试版本与独立测试账号；执行前清理上一条用例残留状态 | K15: 连续两次进入首页并点击权限修复入口 | L15: 第二次不重复触发不可用的系统首次授权框；改为引导用户进入系统设置 | M15: 不涉及 | N15: 不涉及 | O15: 操作截图、App 控制台日志 | P15: 未执行
A16: COM-013 | B16: App 公共功能 | C16: 状态恢复 | D16: 已完成绑定与引导时冷启动恢复首页 | E16: P0 | F16: iOS/Android | G16: App 单端 | H16: UI 自动化/人工 | I16: 本地保存有效设备与已完成引导标记 | J16: 使用当前测试版本与独立测试账号；执行前清理上一条用例残留状态 | K16: 杀进程；重新启动；等待启动恢复完成 | L16: 直接进入当前 TonoCard 首页；不回到扫描或引导页；连接状态按真实链路更新 | M16: 不涉及 | N16: 不涉及 | O16: 操作截图、App 控制台日志 | P16: 未执行
A17: COM-014 | B17: App 公共功能 | C17: 状态恢复 | D17: 绑定后初始化未完成时重启的恢复行为 | E17: P1 | F17: iOS | G17: App 单端 | H17: UI 自动化/人工 | I17: 设备已保存；已进入初始化向导；资料表单可已提交或未提交；引导未走完（无完成标记） | J17: 使用当前测试版本与独立测试账号；执行前清理上一条用例残留状态 | K17: 1. 进入绑定后的初始化向导； 2. 可选：完成资料表单（秘书名+称呼必填）后进入演示屏； 3. 在向导中途杀进程并重启； 4. 观察是否回到绑定流/向导/首页，以及资料是否仍在。 | L17: App：不重复扫描绑定已保存设备；不得误判为已完成引导而直进首页； 若资料已提交：秘书名/称呼仍落盘（设置可核对）； 向导进度不保证续跑到杀进程前那一屏（按产品可重进向导）； 不得仅因 WS 曾断开就写成「已完成」。 | M17: 不涉及 | N17: 不涉及 | O17: 操作截图、App 控制台日志 | P17: 未执行 | R17: 2026-08-13 更新：初始化改为旁白+资料表单+五屏引导；完成门闩=资料已提交+✿END✿+引导台账settled，非断连即完成。Android 表单流未完全对齐，本条以 iOS 为准。
A18: COM-015 | B18: App 公共功能 | C18: 状态恢复 | D18: 启动期间前后台切换保持单一根页面 | E18: P2 | F18: iOS/Android | G18: App 单端 | H18: UI 自动化/人工 | I18: App 冷启动且正在恢复状态 | J18: 使用当前测试版本与独立测试账号；执行前清理上一条用例残留状态 | K18: 启动后立即切后台再回前台；重复两次 | L18: 不会叠加多个合规、绑定或首页页面；无黑屏；启动任务不重复创建服务对象 | M18: 不涉及 | N18: 不涉及 | O18: 操作截图、App 控制台日志 | P18: 未执行
A19: COM-016 | B19: App 公共功能 | C19: 首页 | D19: 当前首页布局与核心入口完整 | E19: P0 | F19: iOS/Android | G19: App 单端 | H19: UI 自动化 | I19: 使用 UI 测试模式或已完成绑定引导 | J19: 使用 12 条种子通话数据 | K19: 进入首页；检查标题、连接状态、接管模式、权限卡、个人中心与 AI 分身按钮 | L19: 显示 TonoCard 首页；不存在旧三 Tab；核心入口可见且无遮挡；AI 分身为右下悬浮按钮 | M19: 不涉及 | N19: 不涉及 | O19: 操作截图、App 控制台日志 | P19: 未执行 | R19: 依据 ios/CallMate/App/MainTabView.swift 与 Android MainTabView.kt
A20: COM-017 | B20: App 公共功能 | C20: 首页 | D20: 设备未连接状态展示准确 | E20: P0 | F20: iOS/Android | G20: App 单端 | H20: UI 自动化/人工 | I20: 已绑定但 MCU 不在范围内或关机 | J20: 使用当前测试版本与独立测试账号；执行前清理上一条用例残留状态 | K20: 启动 App；观察顶部设备状态与接管模式区域 | L20: 显示未连接/可重连语义；不得显示已连接、电量或正在工作；需要设备的操作给出明确反馈 | M20: 不涉及 | N20: 不涉及 | O20: 操作截图、App 控制台日志 | P20: 未执行
A21: COM-018 | B21: App 公共功能 | C21: 首页 | D21: 连接状态由连接中切换为已连接 | E21: P1 | F21: iOS/Android | G21: App 单端 | H21: UI 自动化/人工 | I21: MCU 可连接，App 当前未连接 | J21: 使用当前测试版本与独立测试账号；执行前清理上一条用例残留状态 | K21: 发起连接；观察连接中状态；等待 Ctrl ready | L21: 状态顺序合理；连接完成后显示设备信息；不会长时间卡在连接中或闪回未连接 | M21: 不涉及 | N21: 不涉及 | O21: 操作截图、App 控制台日志 | P21: 未执行
A22: COM-019 | B22: App 公共功能 | C22: 接管模式 | D22: 切换为不接管模式 | E22: P0 | F22: iOS/Android | G22: App 单端 | H22: UI 自动化/人工 | I22: 已进入首页且设备连接可用 | J22: 使用当前测试版本与独立测试账号；执行前清理上一条用例残留状态 | K22: 点击不接管；离开首页再返回 | L22: 选中态正确；说明文案表示不由 AI 代接；页面返回后保持选择 | M22: 不涉及 | N22: 不涉及 | O22: 操作截图、App 控制台日志 | P22: 未执行
A23: COM-020 | B23: App 公共功能 | C23: 接管模式 | D23: 切换为陌生来电模式 | E23: P0 | F23: iOS/Android | G23: App 单端 | H23: UI 自动化/人工 | I23: 已进入首页且设备连接可用 | J23: 使用当前测试版本与独立测试账号；执行前清理上一条用例残留状态 | K23: 点击陌生来电；观察说明；重启 App | L23: 陌生来电模式选中并持久化；说明为持续接听陌生来电；不误显示全接管 | M23: 不涉及 | N23: 不涉及 | O23: 操作截图、App 控制台日志 | P23: 未执行
A24: COM-021 | B24: App 公共功能 | C24: 接管模式 | D24: 切换为全接管模式 | E24: P0 | F24: iOS/Android | G24: App 单端 | H24: UI 自动化/人工 | I24: 已进入首页且设备连接可用，产品条件允许全接管 | J24: 使用当前测试版本与独立测试账号；执行前清理上一条用例残留状态 | K24: 点击全接管；处理可能出现的确认/资格提示 | L24: 满足条件时选中全接管；不满足时给出明确原因且不写入无效状态 | M24: 不涉及 | N24: 不涉及 | O24: 操作截图、App 控制台日志 | P24: 未执行
A25: COM-022 | B25: App 公共功能 | C25: 接管模式 | D25: 设备离线时修改模式并在重连后同步 | E25: P1 | F25: iOS/Android | G25: App 单端 | H25: UI 自动化/人工 | I25: 设备已绑定但离线 | J25: 使用当前测试版本与独立测试账号；执行前清理上一条用例残留状态 | K25: 修改接管模式；重启 App；让 MCU 上线 | L25: 本地选择不丢失；重连后自动同步到 MCU；同步失败时显示可重试提示 | M25: 不涉及 | N25: 不涉及 | O25: 操作截图、App 控制台日志 | P25: 未执行
A26: COM-023 | B26: App 公共功能 | C26: AI 分身 | D26: 点击悬浮按钮打开 AI 分身 | E26: P0 | F26: iOS/Android | G26: App 单端 | H26: UI 自动化/人工 | I26: 首页可见且当前无全屏子页面 | J26: 使用当前测试版本与独立测试账号；执行前清理上一条用例残留状态 | K26: 点击右下 AI 分身/AI 秘书悬浮按钮 | L26: 以大尺寸 sheet/底部弹层打开真实 AI 分身页面；背景不可误触；输入区可用 | M26: 不涉及 | N26: 不涉及 | O26: 操作截图、App 控制台日志 | P26: 未执行
A27: COM-024 | B27: App 公共功能 | C27: AI 分身 | D27: 关闭 AI 分身返回原首页位置 | E27: P1 | F27: iOS/Android | G27: App 单端 | H27: UI 自动化/人工 | I27: AI 分身已打开，首页列表已滚动 | J27: 使用当前测试版本与独立测试账号；执行前清理上一条用例残留状态 | K27: 下滑关闭或点击关闭；观察首页滚动位置 | L27: 弹层关闭；首页状态与滚动位置合理保留；悬浮按钮重新出现 | M27: 不涉及 | N27: 不涉及 | O27: 操作截图、App 控制台日志 | P27: 未执行
A28: COM-025 | B28: App 公共功能 | C28: AI 分身 | D28: 通话实时页出现时自动收起 AI 分身 | E28: P0 | F28: iOS/Android | G28: App 单端 | H28: UI 自动化/人工 | I28: AI 分身已打开；可触发一条模拟实时通话事件 | J28: 使用当前测试版本与独立测试账号；执行前清理上一条用例残留状态 | K28: 保持 AI 分身打开；触发实时通话页面展示 | L28: AI 分身立即收起；实时通话页位于最前且可操作；无透明遮罩阻断转真人按钮 | M28: 不涉及 | N28: 不涉及 | O28: 操作截图、App 控制台日志 | P28: 未执行
A29: COM-026 | B29: App 公共功能 | C29: AI 分身 | D29: AI 分身发送文本并显示回复 | E29: P1 | F29: iOS/Android | G29: App 单端 | H29: UI 自动化/人工 | I29: 已连接可用服务端或测试桩 | J29: 使用当前测试版本与独立测试账号；执行前清理上一条用例残留状态 | K29: 打开 AI 分身；输入一条中文消息并发送；再发送英文消息 | L29: 用户消息立即显示；发送中状态明确；回复归属正确；中英文不乱码；失败可重试 | M29: 不涉及 | N29: 不涉及 | O29: 操作截图、App 控制台日志 | P29: 未执行
A30: COM-027 | B30: App 公共功能 | C30: AI 分身 | D30: 重要来电未读角标展示与清除 | E30: P1 | F30: iOS/Android | G30: App 单端 | H30: UI 自动化/人工 | I30: 生成一条尚未在 AI 分身露出的重要来电卡片 | J30: 使用当前测试版本与独立测试账号；执行前清理上一条用例残留状态 | K30: 返回首页查看角标；打开 AI 分身并查看卡片；关闭 | L30: 角标数量正确，超过 9 显示 9+；卡片投递后角标清零；不会重复累计同一通 | M30: 不涉及 | N30: 不涉及 | O30: 操作截图、App 控制台日志 | P30: 未执行
A31: COM-028 | B31: App 公共功能 | C31: 个人中心 | D31: 打开个人中心并返回 | E31: P0 | F31: iOS/Android | G31: App 单端 | H31: UI 自动化/人工 | I31: 已进入首页 | J31: 使用当前测试版本与独立测试账号；执行前清理上一条用例残留状态 | K31: 点击右上个人中心图标；浏览主要入口；返回 | L31: 进入个人中心；设备、音色、记忆、技能、设置等已启用入口可访问；返回首页无状态丢失 | M31: 不涉及 | N31: 不涉及 | O31: 操作截图、App 控制台日志 | P31: 未执行
... A38: COM-035 | B38: App 公共功能 | C38: 通话记录 | D38: 最近通话列表显示方向、号码与时间 | E38: P0 | F38: iOS/Android | G38: App 单端 | H38: UI 自动化/人工 | I38: 准备来电、外呼、未接等多条记录 | J38: 使用当前测试版本与独立测试账号；执行前清理上一条用例残留状态 | K38: 进入首页查看最近通话；切换筛选条件（如有） | L38: 每条记录的方向、显示名/号码、时间、状态和未读样式正确；隐私号码按规则隐藏 | M38: 不涉及 | N38: 不涉及 | O38: 操作截图、App 控制台日志 | P38: 未执行
A39: COM-036 | B39: App 公共功能 | C39: 通话记录 | D39: 长列表滚动与分页 | E39: P1 | F39: iOS/Android | G39: App 单端 | H39: UI 自动化 | I39: 注入至少 40 条通话记录 | J39: 40 条中英混合种子记录 | K39: 从列表顶部连续上滑到第 15 条之后；继续加载；再回到顶部 | L39: 滚动流畅；目标记录可见；分页无重复、漏项和跳动；首页悬浮按钮不遮挡关键行 | M39: 不涉及 | N39: 不涉及 | O39: 操作截图、App 控制台日志 | P39: 未执行 | R39: 对齐现有 CallsListScrollSmoke
A40: COM-037 | B40: App 公共功能 | C40: 通话记录 | D40: 打开来电详情 | E40: P0 | F40: iOS/Android | G40: App 单端 | H40: UI 自动化/人工 | I40: 存在一条已完成来电且有转录/摘要 | J40: 使用当前测试版本与独立测试账号；执行前清理上一条用例残留状态 | K40: 点击该记录；浏览详情各区块；返回 | L40: 详情方向、号码、时间、时长、转录、摘要与列表一致；返回原列表位置 | M40: 不涉及 | N40: 不涉及 | O40: 操作截图、App 控制台日志 | P40: 未执行
A41: COM-038 | B41: App 公共功能 | C41: 通话记录 | D41: 打开外呼详情 | E41: P1 | F41: iOS/Android | G41: App 单端 | H41: UI 自动化/人工 | I41: 存在一条已完成外呼记录 | J41: 使用当前测试版本与独立测试账号；执行前清理上一条用例残留状态 | K41: 点击外呼记录；查看任务目标、结果与转录 | L41: 显示外呼语义与任务信息；不会误标成来电；结束原因与服务端结果一致 | M41: 不涉及 | N41: 不涉及 | O41: 操作截图、App 控制台日志 | P41: 未执行
A42: COM-039 | B42: App 公共功能 | C42: 通话记录 | D42: 删除记录时取消 | E42: P2 | F42: iOS/Android | G42: App 单端 | H42: UI 自动化/人工 | I42: 存在至少一条记录 | J42: 使用当前测试版本与独立测试账号；执行前清理上一条用例残留状态 | K42: 触发删除；在确认弹窗点击取消 | L42: 记录仍存在；详情、录音和摘要均未删除 | M42: 不涉及 | N42: 不涉及 | O42: 操作截图、App 控制台日志 | P42: 未执行
A43: COM-040 | B43: App 公共功能 | C43: 通话记录 | D43: 确认删除单条记录 | E43: P1 | F43: iOS/Android | G43: App 单端 | H43: UI 自动化/人工 | I43: 存在一条可删除记录 | J43: 使用当前测试版本与独立测试账号；执行前清理上一条用例残留状态 | K43: 触发删除并确认；重新进入列表 | L43: 该记录从列表和详情入口消失；其他记录不受影响；无幽灵未读角标 | M43: 不涉及 | N43: 不涉及 | O43: 操作截图、App 控制台日志 | P43: 未执行
A44: COM-041 | B44: App 公共功能 | C44: 通话记录 | D44: 通话录音播放、暂停与进度恢复 | E44: P1 | F44: iOS/Android | G44: App 单端 | H44: UI 自动化/人工 | I44: 存在包含有效录音的通话 | J44: 使用当前测试版本与独立测试账号；执行前清理上一条用例残留状态 | K44: 进入详情；播放 5 秒；暂停；拖动进度；退出再进入 | L44: 音频可播放且不爆音；暂停/拖动生效；退出停止系统音频占用；文件缺失时给出降级提示 | M44: 不涉及 | N44: 不涉及 | O44: 操作截图、App 控制台日志 | P44: 未执行
A45: COM-042 | B45: App 公共功能 | C45: 反馈 | D45: 通话评价与原因选择提交 | E45: P2 | F45: iOS/Android | G45: App 单端 | H45: UI 自动化/人工 | I45: 存在已完成通话详情 | J45: 使用当前测试版本与独立测试账号；执行前清理上一条用例残留状态 | K45: 选择差评；勾选一个原因并输入备注；提交 | L45: 提交状态明确；重复点击不重复提交；敏感内容按规则处理；失败可重试 | M45: 不涉及 | N45: 不涉及 | O45: 操作截图、App 控制台日志 | P45: 未执行
A46: COM-043 | B46: App 公共功能 | C46: 用户反馈 | D46: 设备页提交用户反馈且可选附日志 | E46: P1 | F46: iOS/Android | G46: App 单端 | H46: UI 自动化/人工 | I46: 已进入设备管理，网络可用 | J46: 使用当前测试版本与独立测试账号；执行前清理上一条用例残留状态 | K46: 打开用户反馈；填写描述；分别测试不附日志和附日志提交 | L46: 必填校验正确；上传进度与成功/失败提示明确；附日志前取得用户确认 | M46: 不涉及 | N46: 不涉及 | O46: 操作截图、App 控制台日志 | P46: 未执行
...

Sheet iOS专项
A1: CallMate / TonoCard 测试用例 · iOS 平台专项
A2: 共 30 条；按优先级、平台、组合层级和执行结果筛选。MCU 日志行首为 32.768 kHz raw tick，重启前后禁止直接相减。
A3: 用例 ID | B3: 一级模块 | C3: 二级模块 | D3: 用例标题 | E3: 优先级 | F3: 平台 | G3: 组合层级 | H3: 自动化建议 | I3: 前置条件 | J3: 测试数据 | K3: 操作步骤 | L3: App 预期结果 | M3: MCU 预期结果 | N3: 服务端预期结果 | O3: 证据/日志 | P3: 执行结果 | Q3: 缺陷 ID | R3: 依据/备注
A4: IOS-001 | B4: iOS 平台专项 | C4: 蓝牙权限 | D4: 首次扫描触发系统蓝牙权限 | E4: P0 | F4: iOS | G4: 平台专项 | H4: iOS 真机人工 | I4: 全新安装并同意协议，蓝牙权限未决定 | J4: 使用当前测试版本与独立测试账号；执行前清理上一条用例残留状态 | K4: 进入绑定扫描；处理系统蓝牙权限弹窗 | L4: 系统框只出现一次；允许后开始扫描；拒绝后停止扫描并显示系统设置引导 | M4: 不涉及 | N4: 不涉及 | O4: iOS 截图、syslog/App 日志 | P4: 未执行
A5: IOS-002 | B5: iOS 平台专项 | C5: 绑定恢复 | D5: CoreBluetooth 后台恢复已保存设备 | E5: P0 | F5: iOS | G5: 平台专项 | H5: iOS 真机人工 | I5: 已绑定 MCU，允许蓝牙后台模式 | J5: 使用当前测试版本与独立测试账号；执行前清理上一条用例残留状态 | K5: 杀进程；让 MCU 重连或产生可唤醒事件；重新前台 App | L5: 复用同一 BLE 对象图恢复连接；不创建第二条连接；首页状态与真实设备一致 | M5: 不涉及 | N5: 不涉及 | O5: iOS 截图、syslog/App 日志 | P5: 未执行
A6: IOS-003 | B6: iOS 平台专项 | C6: 绑定恢复 | D6: 系统蓝牙关闭再开启自动恢复 | E6: P1 | F6: iOS | G6: 平台专项 | H6: iOS 真机人工 | I6: App 已绑定并连接 MCU | J6: 使用当前测试版本与独立测试账号；执行前清理上一条用例残留状态 | K6: 在控制中心关闭蓝牙；等待首页更新；重新开启 | L6: 及时显示断开；蓝牙恢复后自动扫描/重连；无需清除绑定；不重复弹权限 | M6: 不涉及 | N6: 不涉及 | O6: iOS 截图、syslog/App 日志 | P6: 未执行
A7: IOS-004 | B7: iOS 平台专项 | C7: ANCS | D7: 用户同意后发起 ANCS 开启 | E7: P0 | F7: iOS | G7: 平台专项 | H7: iOS 真机人工 | I7: 已连接 MCU，尚未记录 ANCS 用户同意 | J7: 使用当前测试版本与独立测试账号；执行前清理上一条用例残留状态 | K7: 点击首页来电通知邀请；处理系统通知共享弹窗 | L7: 记录按当前 device UID 隔离；显示正在开启；不在没有端到端证据时直接宣称成功 | M7: 不涉及 | N7: 不涉及 | O7: iOS 截图、syslog/App 日志 | P7: 未执行
A8: IOS-005 | B8: iOS 平台专项 | C8: ANCS | D8: ANCS transport subscribed 不等于投递成功 | E8: P0 | F8: iOS | G8: 平台专项 | H8: 半自动 | I8: MCU 上报 ancs_transport_status=subscribed，但无真实 ANCS packet | J8: 使用协议事件注入 | K8: 进入首页与设备页；等待稳定窗 | L8: 不得仅据 subscribed 显示已授权成功；设备页仍可执行端到端检查 | M8: 不涉及 | N8: 不涉及 | O8: iOS 截图、syslog/App 日志 | P8: 未执行 | R8: 依据 ble-protocol-v2.md §2.2.1
A9: IOS-006 | B9: iOS 平台专项 | C9: ANCS | D9: 真实 ANCS packet 后显示正证据 | E9: P0 | F9: iOS | G9: 平台专项 | H9: iOS 真机人工 | I9: 传输已订阅，可向本机发送真实通知/来电 | J9: 使用当前测试版本与独立测试账号；执行前清理上一条用例残留状态 | K9: 触发一条可投递通知；观察 MCU ancs_status enabled=1 与 App 状态 | L9: 收到 enabled=1 后才记录端到端可用；健康状态不再显示故障横幅 | M9: 不涉及 | N9: 不涉及 | O9: iOS 截图、syslog/App 日志 | P9: 未执行
A10: IOS-007 | B10: iOS 平台专项 | C10: ANCS | D10: ANCS 拒绝后设备页提供恢复引导 | E10: P1 | F10: iOS | G10: 平台专项 | H10: iOS 真机人工 | I10: 用户在系统蓝牙通知共享中选择不允许 | J10: 使用当前测试版本与独立测试账号；执行前清理上一条用例残留状态 | K10: 进入设备管理；点击检查来电通知；按引导进入系统设置 | L10: 说明拒绝原因与恢复路径；不会反复自动弹系统框；返回 App 后重新探测 | M10: 不涉及 | N10: 不涉及 | O10: iOS 截图、syslog/App 日志 | P10: 未执行
A11: IOS-008 | B11: iOS 平台专项 | C11: ANCS | D11: 短暂无正证据不误报首页故障 | E11: P1 | F11: iOS | G11: 平台专项 | H11: iOS 真机人工 | I11: 设备历史已确认 ANCS 健康，本次重连暂未收到新通知 | J11: 使用当前测试版本与独立测试账号；执行前清理上一条用例残留状态 | K11: 重连后保持无通知 45 秒；观察首页 | L11: 不因 transient unconfirmed 弹故障横幅；设备页常驻检查入口仍可用 | M11: 不涉及 | N11: 不涉及 | O11: iOS 截图、syslog/App 日志 | P11: 未执行
A12: IOS-009 | B12: iOS 平台专项 | C12: ANCS | D12: degraded_hfp 状态显示恢复提示 | E12: P0 | F12: iOS | G12: 平台专项 | H12: iOS 真机人工 | I12: 两次端到端探测失败且完成一次强制 BLE 重连 | J12: 使用当前测试版本与独立测试账号；执行前清理上一条用例残留状态 | K12: 让 MCU/App 进入 degraded_hfp；返回首页 | L12: 显示明确的来电通知恢复提示；允许用户进入检查；普通 subscribed 状态不误用该提示 | M12: 不涉及 | N12: 不涉及 | O12: iOS 截图、syslog/App 日志 | P12: 未执行
A13: IOS-010 | B13: iOS 平台专项 | C13: ANCS | D13: 第一条真实 ANCS 自动退出 HFP 兜底 | E13: P0 | F13: iOS | G13: 平台专项 | H13: iOS 真机人工 | I13: 当前处于 degraded_hfp | J13: 使用当前测试版本与独立测试账号；执行前清理上一条用例残留状态 | K13: 触发一条真实 ANCS packet；再触发陌生来电 | L13: 兜底状态清除；后续来电回到 ANCS 主路径；不产生双来电事件 | M13: 不涉及 | N13: 不涉及 | O13: iOS 截图、syslog/App 日志 | P13: 未执行
A14: IOS-011 | B14: iOS 平台专项 | C14: ANCS | D14: 换 MCU 后旧设备同意不串用 | E14: P0 | F14: iOS | G14: 平台专项 | H14: iOS 真机人工 | I14: 设备 A 已同意 ANCS；改为绑定设备 B | J14: 使用当前测试版本与独立测试账号；执行前清理上一条用例残留状态 | K14: 连接设备 B；进入首页和设备页 | L14: 按 B 的 device UID 重新判断同意/证据；不得继承 A 的 enabled 或 degraded 状态 | M14: 不涉及 | N14: 不涉及 | O14: iOS 截图、syslog/App 日志 | P14: 未执行
A15: IOS-012 | B15: iOS 平台专项 | C15: 推送 | D15: APNs token 注册包含环境标识 | E15: P1 | F15: iOS | G15: 平台专项 | H15: iOS 真机人工 | I15: 允许通知，Debug 与 Release 包各一份 | J15: 使用当前测试版本与独立测试账号；执行前清理上一条用例残留状态 | K15: 分别安装并注册远程通知；查看上报日志 | L15: Debug 上报 development，Release 上报 production；token 与当前包环境匹配 | M15: 不涉及 | N15: 不涉及 | O15: iOS 截图、syslog/App 日志 | P15: 未执行
A16: IOS-013 | B16: iOS 平台专项 | C16: 推送 | D16: 服务端不接受 apns_env 时兼容重试 | E16: P2 | F16: iOS | G16: 平台专项 | H16: iOS 真机人工 | I16: 测试服务端对 apns_env 返回 extra_forbidden | J16: 使用当前测试版本与独立测试账号；执行前清理上一条用例残留状态 | K16: 启动注册流程；观察请求重试 | L16: 识别特定错误后去掉字段重试一次；本次运行不无限循环；记录降级日志 | M16: 不涉及 | N16: 不涉及 | O16: iOS 截图、syslog/App 日志 | P16: 未执行
A17: IOS-014 | B17: iOS 平台专项 | C17: 推送 | D17: VoIP 与 Live Activity token 同步 | E17: P2 | F17: iOS | G17: 平台专项 | H17: iOS 真机人工 | I17: 系统支持并已产生对应 token | J17: 使用当前测试版本与独立测试账号；执行前清理上一条用例残留状态 | K17: 启动 App；等待推送注册同步 | L17: 可选 token 正确上报；缺少任一 token 不阻断其他 token；长 token 不被截断 | M17: 不涉及 | N17: 不涉及 | O17: iOS 截图、syslog/App 日志 | P17: 未执行
A18: IOS-015 | B18: iOS 平台专项 | C18: 灵动岛 | D18: 待机灵动岛开关立即生效 | E18: P1 | F18: iOS | G18: 平台专项 | H18: iOS 真机人工 | I18: 支持 ActivityKit 的 iPhone 真机 | J18: 使用当前测试版本与独立测试账号；执行前清理上一条用例残留状态 | K18: 在设置中开启待机灵动岛；回桌面观察；再关闭 | L18: 开启后显示正确待机活动；关闭后结束常驻活动；不残留重复活动 | M18: 不涉及 | N18: 不涉及 | O18: iOS 截图、syslog/App 日志 | P18: 未执行
A19: IOS-016 | B19: iOS 平台专项 | C19: 灵动岛 | D19: 来电代接期间显示实时状态 | E19: P0 | F19: iOS | G19: 平台专项 | H19: iOS 真机人工 | I19: 已开启相关能力并触发真实 AI 代接 | J19: 使用当前测试版本与独立测试账号；执行前清理上一条用例残留状态 | K19: 锁屏观察 Live Activity；经历接听、对话、结束 | L19: 状态按来电→接听→通话→结束更新；号码隐私符合锁屏设置；终态及时收起 | M19: 不涉及 | N19: 不涉及 | O19: iOS 截图、syslog/App 日志 | P19: 未执行
A20: IOS-017 | B20: iOS 平台专项 | C20: 灵动岛 | D20: 灵动岛转真人操作与 App 状态一致 | E20: P0 | F20: iOS | G20: 平台专项 | H20: iOS 真机人工 | I20: AI 已代接且支持转真人 | J20: 使用当前测试版本与独立测试账号；执行前清理上一条用例残留状态 | K20: 从灵动岛执行转真人；回到 App | L20: 只执行一次 handoff；App 实时页同步显示机主接管；不重复 hangup 或重建 AI 会话 | M20: 不涉及 | N20: 不涉及 | O20: iOS 截图、syslog/App 日志 | P20: 未执行
... A33: IOS-030 | B33: iOS 平台专项 | C33: 兼容性 | D33: iOS 26 新样式下悬浮按钮与 sheet | E33: P2 | F33: iOS | G33: 平台专项 | H33: iOS 真机人工 | I33: iOS 26.x 模拟器/真机 | J33: 使用当前测试版本与独立测试账号；执行前清理上一条用例残留状态 | K33: 进入首页并打开/关闭 AI 分身；旋转或切前后台 | L33: 新 glass 样式可见且点击区域正确；sheet 无布局跳变；旧系统分支不受影响 | M33: 不涉及 | N33: 不涉及 | O33: iOS 截图、syslog/App 日志 | P33: 未执行

Sheet Android专项
A1: CallMate / TonoCard 测试用例 · Android 平台专项
A2: 共 30 条；按优先级、平台、组合层级和执行结果筛选。MCU 日志行首为 32.768 kHz raw tick，重启前后禁止直接相减。
A3: 用例 ID | B3: 一级模块 | C3: 二级模块 | D3: 用例标题 | E3: 优先级 | F3: 平台 | G3: 组合层级 | H3: 自动化建议 | I3: 前置条件 | J3: 测试数据 | K3: 操作步骤 | L3: App 预期结果 | M3: MCU 预期结果 | N3: 服务端预期结果 | O3: 证据/日志 | P3: 执行结果 | Q3: 缺陷 ID | R3: 依据/备注
A4: AND-001 | B4: Android 平台专项 | C4: 蓝牙权限 | D4: Android 12+ Nearby Devices 权限授权 | E4: P0 | F4: Android | G4: 平台专项 | H4: Android 真机人工 | I4: Android 12+，Nearby devices 未授权 | J4: 使用当前测试版本与独立测试账号；执行前清理上一条用例残留状态 | K4: 进入绑定扫描；允许蓝牙扫描/连接权限 | L4: 授权说明与系统框匹配；允许后开始扫描；不额外索取无关定位权限 | M4: 不涉及 | N4: 不涉及 | O4: Android 截图、logcat | P4: 未执行
A5: AND-002 | B5: Android 平台专项 | C5: 蓝牙权限 | D5: 拒绝 Nearby Devices 后恢复 | E5: P1 | F5: Android | G5: 平台专项 | H5: Android 真机人工 | I5: 已拒绝蓝牙扫描/连接权限 | J5: 使用当前测试版本与独立测试账号；执行前清理上一条用例残留状态 | K5: 再次进入绑定；点击恢复入口；在系统设置允许并返回 | L5: 不死循环弹框；返回后自动重新检查权限并开始扫描 | M5: 不涉及 | N5: 不涉及 | O5: Android 截图、logcat | P5: 未执行
A6: AND-003 | B6: Android 平台专项 | C6: 来电权限 | D6: 电话状态/通话相关权限按需申请 | E6: P0 | F6: Android | G6: 平台专项 | H6: Android 真机人工 | I6: 新安装，电话相关权限未决定 | J6: 使用当前测试版本与独立测试账号；执行前清理上一条用例残留状态 | K6: 完成绑定并开启接管；触发需要来电感知的功能 | L6: 只在需要时申请；用途说明准确；拒绝后不声称能完整感知来电 | M6: 不涉及 | N6: 不涉及 | O6: Android 截图、logcat | P6: 未执行
A7: AND-004 | B7: Android 平台专项 | C7: 通知监听 | D7: 引导开启 NotificationListenerService | E7: P0 | F7: Android | G7: 平台专项 | H7: Android 真机人工 | I7: 通知访问权限未开 | J7: 使用当前测试版本与独立测试账号；执行前清理上一条用例残留状态 | K7: 进入权限卡/设备页；点击通知监听引导；在系统设置开启后返回 | L7: 返回后检测到服务已启用；权限卡更新；不会把它描述为 Apple ANCS | M7: 不涉及 | N7: 不涉及 | O7: Android 截图、logcat | P7: 未执行
A8: AND-005 | B8: Android 平台专项 | C8: 通知监听 | D8: 通知监听探针成功回写 MCU | E8: P0 | F8: Android | G8: 平台专项 | H8: Android 真机人工 | I8: 通知访问已开，App 与 MCU 连接 | J8: 使用当前测试版本与独立测试账号；执行前清理上一条用例残留状态 | K8: 触发测试通知探针；观察 App 与 BLE 控制日志 | L8: App 识别测试通知并向 MCU 回写 Android 对等状态；首页显示链路可用 | M8: 不涉及 | N8: 不涉及 | O8: Android 截图、logcat | P8: 未执行
A9: AND-006 | B9: Android 平台专项 | C9: 通知监听 | D9: 通知访问被系统撤销后的提示 | E9: P1 | F9: Android | G9: 平台专项 | H9: Android 真机人工 | I9: 先开启通知访问，再从系统设置撤销 | J9: 使用当前测试版本与独立测试账号；执行前清理上一条用例残留状态 | K9: 回到 App；重启；查看首页 | L9: 检测撤销并提示恢复；不沿用旧成功缓存；普通来电策略按降级能力执行 | M9: 不涉及 | N9: 不涉及 | O9: Android 截图、logcat | P9: 未执行
A10: AND-007 | B10: Android 平台专项 | C10: 平台语义 | D10: Android 不展示 iOS ANCS 专属入口 | E10: P1 | F10: Android | G10: 平台专项 | H10: Android 真机人工 | I10: 进入首页与设备管理 | J10: 使用当前测试版本与独立测试账号；执行前清理上一条用例残留状态 | K10: 浏览所有权限与设备设置 | L10: 不出现 ANCS、通知共享等 iOS 专属文案；使用通知监听/HFP 对等描述 | M10: 不涉及 | N10: 不涉及 | O10: Android 截图、logcat | P10: 未执行
A11: AND-008 | B11: Android 平台专项 | C11: 来电识别 | D11: HFP +CLIP 获取陌生号码 | E11: P0 | F11: Android | G11: 平台专项 | H11: Android 真机人工 | I11: MCU 与 Android 建立 HFP，来电号码不在联系人中 | J11: 使用当前测试版本与独立测试账号；执行前清理上一条用例残留状态 | K11: 从另一手机拨入；观察来电事件与 UI | L11: 号码与 sid 正确进入会话；标记陌生人；按当前接管模式决策 | M11: 不涉及 | N11: 不涉及 | O11: Android 截图、logcat | P11: 未执行
A12: AND-009 | B12: Android 平台专项 | C12: 来电识别 | D12: PBAP 解析联系人后直通 | E12: P0 | F12: Android | G12: 平台专项 | H12: Android 真机人工 | I12: 来电号码已存入通讯录并允许联系人访问 | J12: 使用当前测试版本与独立测试账号；执行前清理上一条用例残留状态 | K12: 拨入联系人来电；观察 caller_resolved 与 App 决策 | L12: 显示联系人名称；取消/阻止 AI 接管；不发 answer/audio_start | M12: 不涉及 | N12: 不涉及 | O12: Android 截图、logcat | P12: 未执行
A13: AND-010 | B13: Android 平台专项 | C13: 来电识别 | D13: caller_resolved 早于 incoming_call | E13: P0 | F13: Android | G13: 平台专项 | H13: Android 真机人工 | I13: 可注入 PBAP 先完成的时序 | J13: 使用当前测试版本与独立测试账号；执行前清理上一条用例残留状态 | K13: 先收到 caller_resolved，再收到同 sid incoming_call | L13: 会话单一且 sid 有效；不因顺序变化丢失联系人结果或创建两次 UI | M13: 不涉及 | N13: 不涉及 | O13: Android 截图、logcat | P13: 未执行
A14: AND-011 | B14: Android 平台专项 | C14: 来电识别 | D14: 缺少 CLIP 时隐藏号码降级 | E14: P1 | F14: Android | G14: 平台专项 | H14: Android 真机人工 | I14: 运营商/来电设置隐藏号码 | J14: 使用当前测试版本与独立测试账号；执行前清理上一条用例残留状态 | K14: 拨入隐藏号码；等待接管判断 | L14: 显示未知/隐藏号码；不使用上一次号码；策略按未知来电执行 | M14: 不涉及 | N14: 不涉及 | O14: Android 截图、logcat | P14: 未执行
A15: AND-012 | B15: Android 平台专项 | C15: 后台 | D15: 屏幕熄灭时收到来电并启动协调器 | E15: P0 | F15: Android | G15: 平台专项 | H15: Android 真机人工 | I15: App 在后台，电池优化未限制，BLE/HFP 已连 | J15: 使用当前测试版本与独立测试账号；执行前清理上一条用例残留状态 | K15: 熄屏后拨入陌生来电 | L15: 协调器在允许的后台窗口处理；通知与通话 UI 可见；不需要手动先打开 App | M15: 不涉及 | N15: 不涉及 | O15: Android 截图、logcat | P15: 未执行
... A33: AND-030 | B33: Android 平台专项 | C33: 兼容性 | D33: 厂商后台策略组合验证 | E33: P2 | F33: Android | G33: 平台专项 | H33: Android 真机人工 | I33: 至少选择 Pixel 与一台国产 ROM | J33: 使用当前测试版本与独立测试账号；执行前清理上一条用例残留状态 | K33: 按默认、允许自启动、受限后台三种设置执行来电 | L33: 记录可复现差异；应用在可申请范围内给出设置引导；无无限自启或耗电异常 | M33: 不涉及 | N33: 不涉及 | O33: Android 截图、logcat | P33: 未执行

Sheet App_MCU
A1: CallMate / TonoCard 测试用例 · App + MCU
A2: 共 52 条；按优先级、平台、组合层级和执行结果筛选。MCU 日志行首为 32.768 kHz raw tick，重启前后禁止直接相减。
A3: 用例 ID | B3: 一级模块 | C3: 二级模块 | D3: 用例标题 | E3: 优先级 | F3: 平台 | G3: 组合层级 | H3: 自动化建议 | I3: 前置条件 | J3: 测试数据 | K3: 操作步骤 | L3: App 预期结果 | M3: MCU 预期结果 | N3: 服务端预期结果 | O3: 证据/日志 | P3: 执行结果 | Q3: 缺陷 ID | R3: 依据/备注
A4: MCU-001 | B4: App + MCU | C4: 扫描绑定 | D4: 扫描仅展示符合条件的 TonoCard 设备 | E4: P0 | F4: iOS/Android | G4: App + MCU | H4: 真机半自动 | I4: 附近同时存在目标 MCU、普通 BLE 外设和弱信号目标设备 | J4: 使用当前测试版本与独立测试账号；执行前清理上一条用例残留状态 | K4: 进入扫描页；等待两轮扫描；比较设备列表 | L4: 只展示满足名称/服务/RSSI 策略的可绑定设备；列表稳定且不重复 | M4: 目标 MCU 正常广播 v2 Service；非目标设备不受影响 | N4: 不涉及 | O4: App 日志、BLE 抓包/控制日志、MCU 日志 | P4: 未执行
A5: MCU-002 | B5: App + MCU | C5: 扫描绑定 | D5: RSSI 过滤与距离提示 | E5: P1 | F5: iOS/Android | G5: App + MCU | H5: 真机半自动 | I5: 目标 MCU 可在近、中、远三档距离移动 | J5: 使用当前测试版本与独立测试账号；执行前清理上一条用例残留状态 | K5: 分别在三档距离刷新扫描；尝试选择极弱信号设备 | L5: 近距离可连接；弱信号有明确提示或被过滤；不会选错同名设备 | M5: 广播持续且设备身份不变 | N5: 不涉及 | O5: App 日志、BLE 抓包/控制日志、MCU 日志 | P5: 未执行
A6: MCU-003 | B6: App + MCU | C6: 扫描绑定 | D6: 多个同名设备按设备标识区分 | E6: P0 | F6: iOS/Android | G6: App + MCU | H6: 真机半自动 | I6: 附近至少两块同名前缀 MCU | J6: 使用当前测试版本与独立测试账号；执行前清理上一条用例残留状态 | K6: 进入扫描页；记录列表；分别尝试绑定指定设备 | L6: 列表显示足够的区分信息；用户选中的设备与最终 device_id 一致 | M6: 被选择设备建立连接；另一设备不被误 attach | N6: 不涉及 | O6: App 日志、BLE 抓包/控制日志、MCU 日志 | P6: 未执行
A7: MCU-004 | B7: App + MCU | C7: 扫描绑定 | D7: 绑定过程中设备离开范围 | E7: P1 | F7: iOS/Android | G7: App + MCU | H7: 真机半自动 | I7: 目标 MCU 可在连接握手中关机 | J7: 使用当前测试版本与独立测试账号；执行前清理上一条用例残留状态 | K7: 点击设备后立即关机；等待失败；重新开机重试 | L7: 首次失败可理解且可重试；页面不永久卡在连接中；重试成功 | M7: 首次连接中断后释放连接资源；重启后继续广播 | N7: 不涉及 | O7: App 日志、BLE 抓包/控制日志、MCU 日志 | P7: 未执行
A8: MCU-005 | B8: App + MCU | C8: 扫描绑定 | D8: 绑定成功后保存并冷启动重连 | E8: P0 | F8: iOS/Android | G8: App + MCU | H8: 真机半自动 | I8: 全新安装，MCU 未绑定当前 App | J8: 使用当前测试版本与独立测试账号；执行前清理上一条用例残留状态 | K8: 完成扫描、连接、授权与绑定；杀进程；重新启动 | L8: 保存正确 peripheral/device_id；启动后进入恢复路径并自动重连 | M8: 保存/保持必要 bond；重连后 app_attach 成功 | N8: 不涉及 | O8: App 日志、BLE 抓包/控制日志、MCU 日志 | P8: 未执行
A9: MCU-006 | B9: App + MCU | C9: 协议协商 | D9: app_attach 协商 BLE v2 | E9: P0 | F9: iOS/Android | G9: App + MCU | H9: 协议自动化+真机 | I9: App 与 v2 MCU 建立 Ctrl 通道 | J9: 使用控制日志核对 | K9: 观察首个 attach request/result 与页面状态 | L9: 只按 v2 单信封发送；收到 proto_ver=2 后进入 ready；不发送 legacy cmd | M9: 返回 rpc2/frame4/data-merged/bidir 能力和固件版本 | N9: 不涉及 | O9: App 日志、BLE 抓包/控制日志、MCU 日志 | P9: 未执行 | R9: 依据 docs/ble-protocol-v2.md §6
A10: MCU-007 | B10: App + MCU | C10: 协议协商 | D10: 不兼容协议版本阻断业务 | E10: P0 | F10: iOS/Android | G10: App + MCU | H10: 真机半自动 | I10: 使用返回 proto_ver 非 2 的测试固件/桩 | J10: 使用当前测试版本与独立测试账号；执行前清理上一条用例残留状态 | K10: 建立连接并等待协商 | L10: 显示固件不兼容或需升级；不得继续发送通话/OTA命令 | M10: 返回明确版本或错误；不进入 active owner 状态 | N10: 不涉及 | O10: App 日志、BLE 抓包/控制日志、MCU 日志 | P10: 未执行
A11: MCU-008 | B11: App + MCU | C11: 设备信息 | D11: get_info 返回设备身份、固件与电量 | E11: P0 | F11: iOS/Android | G11: App + MCU | H11: 真机半自动 | I11: Ctrl ready | J11: 使用当前测试版本与独立测试账号；执行前清理上一条用例残留状态 | K11: 打开设备管理；触发设备信息读取 | L11: 显示 device_id、固件版本、电量、充电状态；空字段有降级占位 | M11: 单次 request 返回 result 载荷；主动 device_info 与查询结果一致 | N11: 不涉及 | O11: App 日志、BLE 抓包/控制日志、MCU 日志 | P11: 未执行
A12: MCU-009 | B12: App + MCU | C12: 设备信息 | D12: device_id 延迟到达时再启用依赖功能 | E12: P0 | F12: iOS/Android | G12: App + MCU | H12: 真机半自动 | I12: 模拟连接成功但 device_id 稍后到达 | J12: 使用当前测试版本与独立测试账号；执行前清理上一条用例残留状态 | K12: 启动 App；观察设备页与通话能力；等待 device_id | L12: device_id 未就绪时不连接云端或串用旧 ID；到达后自动解锁依赖功能 | M12: 在 get_info/device_info 就绪时提供当前硬件 ID | N12: 不涉及 | O12: App 日志、BLE 抓包/控制日志、MCU 日志 | P12: 未执行
A13: MCU-010 | B13: App + MCU | C13: Ctrl 分帧 | D13: 0x51 COMPLETE 短 JSON 正常收发 | E13: P0 | F13: iOS/Android | G13: App + MCU | H13: 真机半自动 | I13: MTU 足够，发送短 get_info | J13: 使用当前测试版本与独立测试账号；执行前清理上一条用例残留状态 | K13: 执行命令并记录原始帧 | L13: 正确解析 4B 头与 JSON-RPC；按 id 完成 pending | M13: 按 COMPLETE 帧解析并返回标准 result 对象 | N13: 不涉及 | O13: App 日志、BLE 抓包/控制日志、MCU 日志 | P13: 未执行
A14: MCU-011 | B14: App + MCU | C14: Ctrl 分帧 | D14: MTU 23 下长控制消息分片重组 | E14: P0 | F14: iOS/Android | G14: App + MCU | H14: 真机半自动 | I14: 强制 ATT MTU 23 或等效桩，准备 >单帧的 param_set | J14: 使用当前测试版本与独立测试账号；执行前清理上一条用例残留状态 | K14: 发送长请求；观察 FIRST/CONT/LAST；等待响应 | L14: 按片间隔重组成功；UI 不超时；payload 内容无截断 | M14: 每片刷新 500ms 老化计时；完整后只执行一次 | N14: 不涉及 | O14: App 日志、BLE 抓包/控制日志、MCU 日志 | P14: 未执行
A15: MCU-012 | B15: App + MCU | C15: Ctrl 分帧 | D15: 丢失中间分片后下一条消息自愈 | E15: P1 | F15: iOS/Android | G15: App + MCU | H15: 真机半自动 | I15: 可注入丢弃一片 Ctrl 帧 | J15: 使用当前测试版本与独立测试账号；执行前清理上一条用例残留状态 | K15: 发送长请求并丢中间片；随后发送新的 COMPLETE 请求 | L15: 首条按超时失败且可重试；第二条正常解析；链路不永久失步 | M15: 丢弃未完成重组；新 FIRST/COMPLETE 清理旧状态 | N15: 不涉及 | O15: App 日志、BLE 抓包/控制日志、MCU 日志 | P15: 未执行
A16: MCU-013 | B16: App + MCU | C16: Ctrl 分帧 | D16: 分片间隔超过 500ms 触发老化 | E16: P2 | F16: iOS/Android | G16: App + MCU | H16: 真机半自动 | I16: 可控制分片发送间隔 | J16: 使用当前测试版本与独立测试账号；执行前清理上一条用例残留状态 | K16: 发送 FIRST；等待 >500ms；再发 LAST | L16: 请求失败并记录可诊断错误；App pending 最终清理 | M16: 老化丢弃半包，不执行部分 JSON；后续消息可用 | N16: 不涉及 | O16: App 日志、BLE 抓包/控制日志、MCU 日志 | P16: 未执行
A17: MCU-014 | B17: App + MCU | C17: Ctrl 分帧 | D17: 消息超过 2KB 返回 message too large | E17: P1 | F17: iOS/Android | G17: App + MCU | H17: 真机半自动 | I17: 构造 >2048B 控制消息 | J17: 使用当前测试版本与独立测试账号；执行前清理上一条用例残留状态 | K17: 尝试发送；观察本地预警或 MCU error | L17: 优先本地阻止并提示；若已发送，识别 -32001；不崩溃 | M17: 不分配无界内存；返回 -32001 或安全丢弃并计数 | N17: 不涉及 | O17: App 日志、BLE 抓包/控制日志、MCU 日志 | P17: 未执行
A18: MCU-015 | B18: App + MCU | C18: JSON-RPC | D18: 成功 result 必须为对象 | E18: P1 | F18: iOS/Android | G18: App + MCU | H18: 真机半自动 | I18: 使用正常 param_set/get_info | J18: 使用当前测试版本与独立测试账号；执行前清理上一条用例残留状态 | K18: 执行请求；检查响应 envelope | L18: 接受 result:{} 或带字段对象；不依赖裸整数 ack | M18: 成功统一返回 JSON 对象 | N18: 不涉及 | O18: App 日志、BLE 抓包/控制日志、MCU 日志 | P18: 未执行
A19: MCU-016 | B19: App + MCU | C19: JSON-RPC | D19: 无 id 的 incoming_call request 被丢弃 | E19: P0 | F19: iOS/Android | G19: App + MCU | H19: 真机半自动 | I19: 注入缺少 id 的 MCU→App incoming_call | J19: 使用当前测试版本与独立测试账号；执行前清理上一条用例残留状态 | K19: 观察 App 事件与回包 | L19: 不创建来电会话且不回 result；记录协议错误 | M19: 测试桩看到无 result；真实 MCU不得发送此形态 | N19: 不涉及 | O19: App 日志、BLE 抓包/控制日志、MCU 日志 | P19: 未执行
A20: MCU-017 | B20: App + MCU | C20: JSON-RPC | D20: 未知 method 返回标准错误 | E20: P2 | F20: iOS/Android | G20: App + MCU | H20: 真机半自动 | I20: 可向 MCU 发送不存在的方法 | J20: 使用当前测试版本与独立测试账号；执行前清理上一条用例残留状态 | K20: 发送 unknown_method request | L20: 识别 -32601 并清理 pending；UI不展示泛化成功 | M20: 返回 method not found，不崩溃或静默吞掉 | N20: 不涉及 | O20: App 日志、BLE 抓包/控制日志、MCU 日志 | P20: 未执行
A21: MCU-018 | B21: App + MCU | C21: JSON-RPC | D21: 非法参数返回 -32602 | E21: P1 | F21: iOS/Android | G21: App + MCU | H21: 真机半自动 | I21: 构造缺少 sid/phone 的命令 | J21: 使用当前测试版本与独立测试账号；执行前清理上一条用例残留状态 | K21: 分别发送 answer、dial 的非法请求 | L21: 显示/记录参数错误；不改变本地通话状态 | M21: 返回 -32602；不执行 HFP 操作 | N21: 不涉及 | O21: App 日志、BLE 抓包/控制日志、MCU 日志 | P21: 未执行
... A55: MCU-052 | B55: App + MCU | C55: 心跳 | D55: app_heartbeat 丢失后 owner 释放 | E55: P1 | F55: iOS/Android | G55: App + MCU | H55: 真机半自动 | I55: App 已 attach 成为 owner | J55: 使用当前测试版本与独立测试账号；执行前清理上一条用例残留状态 | K55: 阻断 heartbeat 并等待 MCU超时；再由同/另一App attach | L55: 原 App显示断连或重新attach；不会认为仍持有 owner | M55: 超时释放 owner和相关会话资源；新 attach 可成功 | N55: 不涉及 | O55: App 日志、BLE 抓包/控制日志、MCU 日志 | P55: 未执行

Sheet App_服务端
A1: CallMate / TonoCard 测试用例 · App + 服务端
A2: 共 45 条；按优先级、平台、组合层级和执行结果筛选。MCU 日志行首为 32.768 kHz raw tick，重启前后禁止直接相减。
A3: 用例 ID | B3: 一级模块 | C3: 二级模块 | D3: 用例标题 | E3: 优先级 | F3: 平台 | G3: 组合层级 | H3: 自动化建议 | I3: 前置条件 | J3: 测试数据 | K3: 操作步骤 | L3: App 预期结果 | M3: MCU 预期结果 | N3: 服务端预期结果 | O3: 证据/日志 | P3: 执行结果 | Q3: 缺陷 ID | R3: 依据/备注
A4: SRV-001 | B4: App + 服务端 | C4: 注册鉴权 | D4: 首次安装 POST /api/app/register | E4: P0 | F4: iOS/Android | G4: App + 服务端 | H4: 接口自动化+App 集成 | I4: 新安装且服务端不存在 app_code | J4: iOS os_type=1，Android=2 | K4: 同意协议并触发 bootstrap；检查注册请求与响应 | L4: 保存服务端权威 app_code；注册成功后继续 token 流程 | M4: 不涉及 | N4: 接受 pid_id、app_code、os_type；返回 data.app_code | O4: App 网络日志、HTTP/WS/QUIC 状态、服务端 request_id/session_id | P4: 未执行
A5: SRV-002 | B5: App + 服务端 | C5: 注册鉴权 | D5: register 可改写 app_code | E5: P1 | F5: iOS/Android | G5: App + 服务端 | H5: 接口自动化+App 集成 | I5: 测试服务端返回与请求不同的 app_code | J5: 使用当前测试版本与独立测试账号；执行前清理上一条用例残留状态 | K5: 触发注册；重启 App；再次取 token | L5: 以响应 app_code 覆盖本地并持久化；后续请求使用新值 | M5: 不涉及 | N5: 稳定返回权威 app_code；旧值不会生成重复身份 | O5: App 网络日志、HTTP/WS/QUIC 状态、服务端 request_id/session_id | P5: 未执行
A6: SRV-003 | B6: App + 服务端 | C6: 注册鉴权 | D6: register 忽略未知可选字段 | E6: P1 | F6: iOS/Android | G6: App + 服务端 | H6: 接口自动化+App 集成 | I6: 请求包含 apns_env、phone_model 或未来可选字段 | J6: 使用当前测试版本与独立测试账号；执行前清理上一条用例残留状态 | K6: 提交注册；检查HTTP状态 | L6: 2xx 后继续流程；不会因字段兼容问题丢失全部推送注册 | M6: 不涉及 | N6: 采用向前兼容解析，不以 extra_forbid 返回400 | O6: App 网络日志、HTTP/WS/QUIC 状态、服务端 request_id/session_id | P6: 未执行
A7: SRV-004 | B7: App + 服务端 | C7: 注册鉴权 | D7: token 接受 32 位 hex app_code | E7: P0 | F7: iOS/Android | G7: App + 服务端 | H7: 接口自动化+App 集成 | I7: 已有有效32位 app_code | J7: 使用当前测试版本与独立测试账号；执行前清理上一条用例残留状态 | K7: 调用 /api/app/token | L7: 保存JWT并解析exp；后续请求带Bearer | M7: 不涉及 | N7: 返回 data.token；token与app_code身份一致 | O7: App 网络日志、HTTP/WS/QUIC 状态、服务端 request_id/session_id | P7: 未执行
A8: SRV-005 | B8: App + 服务端 | C8: 注册鉴权 | D8: token hex失败后 UUID格式重试一次 | E8: P1 | F8: iOS/Android | G8: App + 服务端 | H8: 接口自动化+App 集成 | I8: 服务端仅接受带连字符UUID格式 | J8: 使用当前测试版本与独立测试账号；执行前清理上一条用例残留状态 | K8: 触发取token；记录两次请求 | L8: 第一次非2xx后只用转换格式重试一次；成功后不继续重试 | M8: 不涉及 | N8: 第二次接受同一app_code的UUID表示并签发token | O8: App 网络日志、HTTP/WS/QUIC 状态、服务端 request_id/session_id | P8: 未执行
A9: SRV-006 | B9: App + 服务端 | C9: 注册鉴权 | D9: JWT 到期前5分钟主动刷新 | E9: P0 | F9: iOS/Android | G9: App + 服务端 | H9: 接口自动化+App 集成 | I9: token exp 距当前不足5分钟 | J9: 使用当前测试版本与独立测试账号；执行前清理上一条用例残留状态 | K9: 调用一个需鉴权接口 | L9: 先刷新token再发业务请求；不并发刷新多次 | M9: 不涉及 | N9: 签发新token；旧token语义稳定 | O9: App 网络日志、HTTP/WS/QUIC 状态、服务端 request_id/session_id | P9: 未执行
A10: SRV-007 | B10: App + 服务端 | C10: 注册鉴权 | D10: 业务接口401后刷新并重试一次 | E10: P0 | F10: iOS/Android | G10: App + 服务端 | H10: 接口自动化+App 集成 | I10: 服务端让首个device/report或summary返回401 | J10: 使用当前测试版本与独立测试账号；执行前清理上一条用例残留状态 | K10: 执行业务动作；观察token刷新和重试 | L10: 清除旧JWT；刷新后重试原请求一次；成功更新UI | M10: 不涉及 | N10: 401只表示token失效；新token请求成功；相同业务不重复落库 | O10: App 网络日志、HTTP/WS/QUIC 状态、服务端 request_id/session_id | P10: 未执行
A11: SRV-008 | B11: App + 服务端 | C11: 注册鉴权 | D11: unknown app code触发重新注册 | E11: P0 | F11: iOS/Android | G11: App + 服务端 | H11: 接口自动化+App 集成 | I11: device/report返回400 detail=unknown app code | J11: 使用当前测试版本与独立测试账号；执行前清理上一条用例残留状态 | K11: 连接设备并触发上报 | L11: 清hasRegistered；重新register并采纳权威code；再重试一次 | M11: 不涉及 | N11: register/token/report校验口径一致；最终绑定上报成功 | O11: App 网络日志、HTTP/WS/QUIC 状态、服务端 request_id/session_id | P11: 未执行
A12: SRV-009 | B12: App + 服务端 | C12: 设备上报 | D12: device/report 使用MCU硬件ID | E12: P0 | F12: iOS/Android | G12: App + 服务端 | H12: 接口自动化+App 集成 | I12: App已连接设备并取得runtimeMCUDeviceID | J12: 使用当前测试版本与独立测试账号；执行前清理上一条用例残留状态 | K12: 触发通话前上报；检查body | L12: device_id来自当前MCU而非手机ID；app_code和本次bluetooth_id正确 | M12: 不涉及 | N12: 将设备绑定到对应App实例；返回可诊断request_id | O12: App 网络日志、HTTP/WS/QUIC 状态、服务端 request_id/session_id | P12: 未执行
A13: SRV-010 | B13: App + 服务端 | C13: 设备上报 | D13: device/report失败不阻断实时通话 | E13: P1 | F13: iOS/Android | G13: App + 服务端 | H13: 接口自动化+App 集成 | I13: 让上报返回5xx但token仍有效 | J13: 使用当前测试版本与独立测试账号；执行前清理上一条用例残留状态 | K13: 发起一通允许的模拟/真实通话 | L13: 记录上报失败但继续建立实时通话；UI不误报设备未连接 | M13: 不涉及 | N13: 上报失败与chat服务解耦；chat可接受有效token/device_id | O13: App 网络日志、HTTP/WS/QUIC 状态、服务端 request_id/session_id | P13: 未执行
A14: SRV-011 | B14: App + 服务端 | C14: 身份隔离 | D14: 未取得当前MCU device_id禁止连接通话服务 | E14: P0 | F14: iOS/Android | G14: App + 服务端 | H14: 接口自动化+App 集成 | I14: App无MCU或get_info尚未返回 | J14: 使用当前测试版本与独立测试账号；执行前清理上一条用例残留状态 | K14: 尝试发起模拟外的BLE实时通话 | L14: 在本地阻断并提示连接设备；不得沿用上一块MCU ID | M14: 不涉及 | N14: 不应收到带伪造/旧Device-Id的连接 | O14: App 网络日志、HTTP/WS/QUIC 状态、服务端 request_id/session_id | P14: 未执行
A15: SRV-012 | B15: App + 服务端 | C15: 身份隔离 | D15: 切换MCU后云端会话使用新Device-Id | E15: P0 | F15: iOS/Android | G15: App + 服务端 | H15: 接口自动化+App 集成 | I15: 先用设备A完成通话，再绑定设备B | J15: 使用当前测试版本与独立测试账号；执行前清理上一条用例残留状态 | K15: 用B发起通话；检查握手与摘要 | L15: 所有新请求使用B；A的摘要/订阅状态不显示到B | M15: 不涉及 | N15: 会话、摘要和权限按B隔离 | O15: App 网络日志、HTTP/WS/QUIC 状态、服务端 request_id/session_id | P15: 未执行
... A48: SRV-045 | B48: App + 服务端 | C48: 网络恢复 | D48: BLE来电WS断开不做无界重连 | E48: P0 | F48: iOS/Android | G48: App + 服务端 | H48: 接口自动化+App 集成 | I48: 真实入站AI通话进行中 | J48: 使用当前测试版本与独立测试账号；执行前清理上一条用例残留状态 | K48: 断开实时服务但保持电话与BLE | L48: 按入站安全策略收尾/挂断，不做常规无限重连；状态回到可用 | M48: 不涉及 | N48: 释放入站session；不保留幽灵并发 | O48: App 网络日志、HTTP/WS/QUIC 状态、服务端 request_id/session_id | P48: 未执行

Sheet 三端通话
A1: CallMate / TonoCard 测试用例 · App + MCU + 服务端
A2: 共 62 条；按优先级、平台、组合层级和执行结果筛选。MCU 日志行首为 32.768 kHz raw tick，重启前后禁止直接相减。
A3: 用例 ID | B3: 一级模块 | C3: 二级模块 | D3: 用例标题 | E3: 优先级 | F3: 平台 | G3: 组合层级 | H3: 自动化建议 | I3: 前置条件 | J3: 测试数据 | K3: 操作步骤 | L3: App 预期结果 | M3: MCU 预期结果 | N3: 服务端预期结果 | O3: 证据/日志 | P3: 执行结果 | Q3: 缺陷 ID | R3: 依据/备注
A4: E2E-001 | B4: App + MCU + 服务端 | C4: 来电主链 | D4: 陌生来电在陌生来电模式下由AI代接 | E4: P0 | F4: iOS/Android | G4: App + MCU + 服务端 | H4: 三端真机人工 | I4: App与MCU连接，模式=陌生来电，云端可用 | J4: 来电号码不在通讯录 | K4: 从来电方拨入；等待接听；说固定语料；听AI回复；由来电方挂断 | L4: 显示正确号码与实时通话；按延迟接听；双向字幕/音频正常；结束生成一条记录 | M4: 上报incoming_call；执行answer；active→audio_streaming；peer ended后复位 | N4: answer前hello成功；处理16k上行并下发24k TTS；结束session并产出摘要 | O4: App日志+截图、MCU日志、服务端session_id、必要时双方录音 | P4: 未执行
A5: E2E-002 | B5: App + MCU + 服务端 | C5: 来电主链 | D5: 联系人来电在陌生来电模式下直通 | E5: P0 | F5: iOS/Android | G5: App + MCU + 服务端 | H5: 三端真机人工 | I5: 模式=陌生来电，号码已存通讯录 | J5: 联系人“测试联系人”拨入 | K5: 拨入；等待超过接听延迟；在手机上接听或挂断 | L5: 显示联系人；不进入AI实时页；不发送answer/audio_start；记录方向正确 | M5: caller_resolved为联系人；保持电话系统处理；不启动Opus | N5: 不创建实时AI会话；无无主摘要任务 | O5: App日志+截图、MCU日志、服务端session_id、必要时双方录音 | P5: 未执行
A6: E2E-003 | B6: App + MCU + 服务端 | C6: 来电主链 | D6: 全接管模式联系人也由AI代接 | E6: P0 | F6: iOS/Android | G6: App + MCU + 服务端 | H6: 三端真机人工 | I6: 模式=全接管且资格满足 | J6: 联系人号码拨入 | K6: 拨入；等待AI接听；进行一轮对话 | L6: 按全接管策略代接；仍显示联系人身份；不误走陌生人提示 | M6: answer/audio_start正常；sid单一 | N6: hello包含isContact=true/callerName；正常对话 | O6: App日志+截图、MCU日志、服务端session_id、必要时双方录音 | P6: 未执行
A7: E2E-004 | B7: App + MCU + 服务端 | C7: 来电主链 | D7: 不接管模式所有来电均直通 | E7: P0 | F7: iOS/Android | G7: App + MCU + 服务端 | H7: 三端真机人工 | I7: 模式=不接管 | J7: 陌生号码拨入 | K7: 拨入并等待15秒；由用户在手机接听/挂断 | L7: 不发起AI代接或云端连接；首页状态可提示但不抢接 | M7: 不接受App answer/audio_start；保持HFP/系统路径 | N7: 无实时AIsession | O7: App日志+截图、MCU日志、服务端session_id、必要时双方录音 | P7: 未执行
A8: E2E-005 | B8: App + MCU + 服务端 | C8: 来电门禁 | D8: 云端hello成功前绝不接听 | E8: P0 | F8: iOS/Android | G8: App + MCU + 服务端 | H8: 自动时间线+真机 | I8: 模式允许代接；人为延迟服务端hello 6秒 | J8: 陌生来电 | K8: 拨入并记录incoming_call、hello、answer时间 | L8: 保持等待状态；只有hello ACK后才发answer；无“电话接了但AI没准备好”窗口 | M8: 收到answer前保持响铃；answer后进入active | N8: 延迟hello但最终建立唯一session | O8: App日志+截图、MCU日志、服务端session_id、必要时双方录音 | P8: 未执行 | R8: Android快速失败2s/硬超时8s按现状校准
A9: E2E-006 | B9: App + MCU + 服务端 | C9: 来电门禁 | D9: 云端hello永久无响应时忽略来电 | E9: P0 | F9: iOS/Android | G9: App + MCU + 服务端 | H9: 三端真机人工 | I9: 模式允许代接；chat连接可建但不回hello | J9: 陌生来电 | K9: 拨入并等待超过最大门禁时间 | L9: 不发answer；向MCU发送ignore/安全收尾；提示云端不可用；不显示已接听 | M9: 保持铃声给用户/系统；收到ignore后进入passthrough；最终终态复位 | N9: 释放未完成连接；无幽灵session | O9: App日志+截图、MCU日志、服务端session_id、必要时双方录音 | P9: 未执行
A10: E2E-007 | B10: App + MCU + 服务端 | C10: 来电门禁 | D10: 完全断网时不代接 | E10: P0 | F10: iOS/Android | G10: App + MCU + 服务端 | H10: 三端真机人工 | I10: 关闭Wi‑Fi与蜂窝数据，BLE/HFP正常 | J10: 陌生来电 | K10: 拨入；等待策略决策；再恢复网络 | L10: 在网络不可用门禁内不answer；首页可累计云端不可达提示；恢复后下一通可用 | M10: 不进入AI音频；本通允许手机正常响铃 | N10: 无连接；恢复后新连接成功 | O10: App日志+截图、MCU日志、服务端session_id、必要时双方录音 | P10: 未执行
A11: E2E-008 | B11: App + MCU + 服务端 | C11: 来电门禁 | D11: BLE信号过弱时默认不代接 | E11: P0 | F11: iOS/Android | G11: App + MCU + 服务端 | H11: 三端真机人工 | I11: 设备RSSI/链路质量低于门禁，弱信号仍接听关闭 | J11: 陌生来电 | K11: 把MCU放到弱信号距离后拨入 | L11: 不answer；显示太远/弱链路提示；避免接通后无音频 | M11: 保持来电但不启动App音频 | N11: 无需建立或及时释放预连接 | O11: App日志+截图、MCU日志、服务端session_id、必要时双方录音 | P11: 未执行
A12: E2E-009 | B12: App + MCU + 服务端 | C12: 来电门禁 | D12: 开启弱信号仍接听后旁路距离门禁 | E12: P1 | F12: iOS/Android | G12: App + MCU + 服务端 | H12: 三端真机人工 | I12: 弱信号仍接听开启，链路仍能传输 | J12: 陌生来电 | K12: 在相同弱信号条件拨入并完成短对话 | L12: 允许代接并明确风险；若音频失败按看门狗收尾；旧弱链路横幅清除 | M12: 正常answer/audio；统计丢包与链路参数 | N12: 会话正常或按媒体失败结束 | O12: App日志+截图、MCU日志、服务端session_id、必要时双方录音 | P12: 未执行
A13: E2E-010 | B13: App + MCU + 服务端 | C13: 来电时序 | D13: 重复incoming_call同id只创建一通 | E13: P0 | F13: iOS/Android | G13: App + MCU + 服务端 | H13: 三端真机人工 | I13: MCU按1Hz重发同id来电request | J13: 同一uid/sid重复15次 | K13: 拨入并让App延迟首次result；观察UI与云端连接 | L13: 只创建一个controller/实时页/hello；每次按协议回相同result；不重复接听 | M13: 重发直到收到result；随后停止；sid不变 | N13: 只产生一个session | O13: App日志+截图、MCU日志、服务端session_id、必要时双方录音 | P13: 未执行
A14: E2E-011 | B14: App + MCU + 服务端 | C14: 来电时序 | D14: 同sid不同消息顺序仍保持单一会话 | E14: P0 | F14: iOS/Android | G14: App + MCU + 服务端 | H14: 三端真机人工 | I14: 可让caller_resolved、incoming_call、call_state接近同时到达 | J14: 同一来电 | K14: 循环执行三种事件顺序 | L14: 身份、策略与状态最终一致；无重复页面/记录；不丢owner判据 | M14: 同sid维持一个call session | N14: 一个session消费音频 | O14: App日志+截图、MCU日志、服务端session_id、必要时双方录音 | P14: 未执行
A15: E2E-012 | B15: App + MCU + 服务端 | C15: 来电时序 | D15: 来电方在AI接听前取消 | E15: P0 | F15: iOS/Android | G15: App + MCU + 服务端 | H15: 三端真机人工 | I15: 服务端预连接中或pickup delay中 | J15: 陌生号码拨入后2秒挂断 | K15: 拨入并快速挂断 | L15: 取消pending answer；收起来电UI；不在终态后补发answer；记录按产品规则标未接 | M15: 上报ended；拒绝迟到answer或返回迟到错误 | N15: 停止预连接，无摘要或生成未接记录所需结果 | O15: App日志+截图、MCU日志、服务端session_id、必要时双方录音 | P15: 未执行
A16: E2E-013 | B16: App + MCU + 服务端 | C16: 来电时序 | D16: 用户在手机上先接听 | E16: P0 | F16: iOS/Android | G16: App + MCU + 服务端 | H16: 三端真机人工 | I16: AI尚未answer | J16: 陌生来电 | K16: 拨入后立即在手机系统界面接听 | L16: 取消AI代接；显示/记录真人接管；不误发hfp_disconnect掐断电话 | M16: call_state证明通话active但非App接管；保持真人音频 | N16: 停止预连接session | O16: App日志+截图、MCU日志、服务端session_id、必要时双方录音 | P16: 未执行
A17: E2E-014 | B17: App + MCU + 服务端 | C17: 来电时序 | D17: 用户在手机上拒接 | E17: P0 | F17: iOS/Android | G17: App + MCU + 服务端 | H17: 三端真机人工 | I17: AI尚未answer | J17: 陌生来电 | K17: 拨入后在手机拒接 | L17: UI及时结束；pending任务清理；下一通可正常代接 | M17: 上报rejected/ended并复位 | N17: 预连接释放 | O17: App日志+截图、MCU日志、服务端session_id、必要时双方录音 | P17: 未执行
A18: E2E-015 | B18: App + MCU + 服务端 | C18: 呼叫等待 | D18: 第一通AI通话中第二通来电不拆音频 | E18: P0 | F18: iOS/Android | G18: App + MCU + 服务端 | H18: 三端真机人工 | I18: 第一通已audio_streaming，运营商支持呼叫等待 | J18: 第二个号码拨入 | K18: 第一通对话时拨入第二通；观察10秒；结束第二通后继续第一通 | L18: 保持第一通sid/字幕/音频；第二通按策略提示或忽略；不切controller | M18: 不因第二通执行audio_stop/hangup第一通；状态机保持 | N18: 第一通session持续；不错误创建第二个占用会话 | O18: App日志+截图、MCU日志、服务端session_id、必要时双方录音 | P18: 未执行
A19: E2E-016 | B19: App + MCU + 服务端 | C19: 双手机 | D19: 双iPhone仅ring_local=1手机代接 | E19: P0 | F19: iOS | G19: App + MCU + 服务端 | H19: 三端真机人工 | I19: 两台已授权iPhone连接同一MCU，来电归属A | J19: 向A号码拨入 | K19: 同时观察A/B App、MCU和云端 | L19: A进入代接；B仅展示必要信息或完全不参赛；B不发answer/hello | M19: 只接受A铃源连接的决策；重发路由正确 | N19: 仅A创建session | O19: App日志+截图、MCU日志、服务端session_id、必要时双方录音 | P19: 未执行
A20: E2E-017 | B20: App + MCU + 服务端 | C20: 双手机 | D20: ring_local=0手机回result后早退 | E20: P0 | F20: iOS | G20: App + MCU + 服务端 | H20: 三端真机人工 | I20: 双iPhone连接同一MCU | J20: 向A号码拨入 | K20: 抓取B收到的信息副本并观察处理 | L20: B按request id回result以免协议重试，但在owner gate早退；无UI/WS | M20: 吸收B unmatched result且不停止A的1Hz重发 | N20: B无session | O20: App日志+截图、MCU日志、服务端session_id、必要时双方录音 | P20: 未执行
... A49: E2E-046 | B49: App + MCU + 服务端 | C49: 外呼网络 | D49: 外呼中断允许一次有界重连 | E49: P0 | F49: iOS/Android | G49: App + MCU + 服务端 | H49: 三端真机人工 | I49: 外呼AI通话进行中 | J49: 测试号码 | K49: 短断chat连接2秒后恢复；再断开超过重连窗 | L49: 第一次在约3秒窗内恢复且不重拨；第二次按策略收尾；无无限重试 | M49: HFP电话在短窗保持；最终只挂一次 | N49: 第一次恢复同业务上下文；超窗释放旧session | O49: App日志+截图、MCU日志、服务端session_id、必要时双方录音 | P49: 未执行
A50: E2E-047 | B50: App + MCU + 服务端 | C50: 外呼UI | D50: 外呼中打开键盘或切页不误挂 | E50: P0 | F50: iOS | G50: App + MCU + 服务端 | H50: 真机人工 | I50: 外呼已接通并显示实时页 | J50: 测试号码 | K50: 弹出键盘、打开sheet、进入后台再返回 | L50: spurious onDisappear不触发挂断；controller仍active；操作返回后字幕继续 | M50: 音频链持续 | N50: session持续 | O50: App日志+截图、MCU日志、服务端session_id、必要时双方录音 | P50: 未执行 | R50: 验证iOS不变量I-2
A51: E2E-048 | B51: App + MCU + 服务端 | C51: 连续通话 | D51: 连续两通来电音频队列不串 | E51: P0 | F51: iOS/Android | G51: App + MCU + 服务端 | H51: 三端真机人工 | I51: 设备和服务正常 | J51: 两个不同陌生号码 | K51: 完成第一通；间隔3秒拨入第二通；两通使用不同固定语料 | L51: 第二通不播放第一通尾音/字幕；sid、记录、摘要独立 | M51: 第一通队列清空；第二通新sid/audio worker | N51: 两个session与摘要严格对应 | O51: App日志+截图、MCU日志、服务端session_id、必要时双方录音 | P51: 未执行
A52: E2E-049 | B52: App + MCU + 服务端 | C52: 连续通话 | D52: 来电结束后立即外呼不复用旧SID | E52: P0 | F52: iOS/Android | G52: App + MCU + 服务端 | H52: 三端真机人工 | I52: 完成一通来电 | J52: 合法外呼号码 | K52: 终态后1秒确认外呼并接通 | L52: 外呼使用新上下文；旧ended/phone_handled迟到不结束外呼 | M52: 为外呼创建新sid；拒绝旧sid命令 | N52: 新outbound session不受旧消息影响 | O52: App日志+截图、MCU日志、服务端session_id、必要时双方录音 | P52: 未执行
A53: E2E-050 | B53: App + MCU + 服务端 | C53: 连续通话 | D53: 外呼结束后立即来电 | E53: P0 | F53: iOS/Android | G53: App + MCU + 服务端 | H53: 三端真机人工 | I53: 完成一通外呼 | J53: 陌生号码随后拨入 | K53: 外呼结束2秒后拨入并完成来电对话 | L53: 来电正常代接；不沿用外呼prompt/systemCallType；记录方向正确 | M53: 新incoming sid和音频链 | N53: 新inbound session与模板 | O53: App日志+截图、MCU日志、服务端session_id、必要时双方录音 | P53: 未执行
A54: E2E-051 | B54: App + MCU + 服务端 | C54: 连续通话 | D54: 50通重复测试无累积卡死 | E54: P1 | F54: iOS/Android | G54: App + MCU + 服务端 | H54: 双机测试台 | I54: 使用双机测试台与稳定网络 | J54: 固定短语料、每通30秒 | K54: 自动执行50通来电/外呼交替；收集每轮工件 | L54: 成功率与失败轮可追踪；无内存/队列持续增长；第50通仍可用 | M54: 无异常重启；音频/控制计数无不可逆累积 | N54: 无幽灵session；并发配额回收 | O54: App日志+截图、MCU日志、服务端session_id、必要时双方录音 | P54: 未执行
A55: E2E-052 | B55: App + MCU + 服务端 | C55: 重要来电 | D55: 重要来电触发机主通知卡 | E55: P0 | F55: iOS/Android | G55: App + MCU + 服务端 | H55: 三端真机人工 | I55: 策略/服务端判定该来电重要 | J55: 测试重要来电脚本 | K55: 完成AI前半段并触发notify_owner/转接建议 | L55: 显示重要来电卡与通知；身份/原因正确；角标增加一次 | M55: 保持通话并按指令显示重要状态 | N55: 工具调用与session一致 | O55: App日志+截图、MCU日志、服务端session_id、必要时双方录音 | P55: 未执行 | R55: 2026-08-13：初始化演示屏重要来电文案改为震动为主，本条机主通知卡逻辑仍验；与 COM-055 文案口径对齐。
A56: E2E-053 | B56: App + MCU + 服务端 | C56: 紧急转接 | D56: 紧急告警开始时MCU显示并震动 | E56: P0 | F56: iOS | G56: App + MCU + 服务端 | H56: 三端真机人工 | I56: AI代接进行中，服务端触发紧急转接流程 | J56: 重要来电固定脚本 | K56: 触发emergency_call_alert start；观察App和MCU30秒内状态 | L56: 显示紧急转接界面/通知且可转真人；不会重复弹多个页面 | M56: 仅IN_CALL接受；显示重要来电场景并长短长循环震动 | N56: orchestrated流程进入允许/告警状态 | O56: App日志+截图、MCU日志、服务端session_id、必要时双方录音 | P56: 未执行
A57: E2E-054 | B57: App + MCU + 服务端 | C57: 紧急转接 | D57: 告警期间MCU PA34单按转真人 | E57: P0 | F57: iOS | G57: App + MCU + 服务端 | H57: 三端真机人工 | I57: 紧急告警窗口active，通话仍IN_CALL且uid有效 | J57: 重要来电固定脚本 | K57: 单按PA34；观察BLE handoff_to_human、App HFP动作与真人通话 | L57: 收到通知后走与灵动岛相同handoffToHuman；停止AI并交给手机；不hangup | M57: 发送一次handoff_to_human；停止震动并确认震动；不落入id-press x5 | N57: 释放AI媒体/并发但不挂蜂窝电话 | O57: App日志+截图、MCU日志、服务端session_id、必要时双方录音 | P57: 未执行 | R57: 回归commit 860b2313
A58: E2E-055 | B58: App + MCU + 服务端 | C58: 紧急转接 | D58: 告警期间重复单按幂等 | E58: P0 | F58: iOS | G58: App + MCU + 服务端 | H58: 三端真机人工 | I58: 上一场景handoff正在执行 | J58: 同一重要来电 | K58: 快速单按PA34三次 | L58: 只执行一次handoff；重复通知不产生多次hfp_disconnect/收尾 | M58: 重复按键被消费且不累计ID连按计数 | N58: 只释放一次session | O58: App日志+截图、MCU日志、服务端session_id、必要时双方录音 | P58: 未执行
A59: E2E-056 | B59: App + MCU + 服务端 | C59: 紧急转接 | D59: 非告警期PA34单按不触发handoff | E59: P1 | F59: iOS | G59: App + MCU + 服务端 | H59: 三端真机人工 | I59: 设备空闲、普通通话、来电响铃三种非告警状态 | J59: 普通测试号码 | K59: 各状态单按PA34 | L59: App不收到handoff_to_human；业务不被误接管 | M59: 按各状态原按键逻辑处理；不发紧急通知 | N59: 无影响 | O59: App日志+截图、MCU日志、服务端session_id、必要时双方录音 | P59: 未执行
A60: E2E-057 | B60: App + MCU + 服务端 | C60: 紧急转接 | D60: 告警end与本地超时同时到达幂等 | E60: P1 | F60: iOS | G60: App + MCU + 服务端 | H60: 三端真机人工 | I60: 告警接近30秒超时，服务端同时发end | J60: 重要来电 | K60: 控制两个事件在100ms内到达 | L60: UI只收起一次；通话状态不被误结束；无重复提示 | M60: app_emergency_alert_end幂等；停止震动并恢复通话UI | N60: 流程进入单一终态 | O60: App日志+截图、MCU日志、服务端session_id、必要时双方录音 | P60: 未执行
A61: E2E-058 | B61: App + MCU + 服务端 | C61: 紧急转接 | D61: 通话结束强制清理紧急告警 | E61: P0 | F61: iOS | G61: App + MCU + 服务端 | H61: 三端真机人工 | I61: 紧急告警进行中 | J61: 重要来电 | K61: 由来电方直接挂断 | L61: 立即结束实时页/通知；无残留告警或后续handoff动作 | M61: APP_EVT_CALL_ENDED停止震动、恢复/退出场景并复位 | N61: session与orchestration清理 | O61: App日志+截图、MCU日志、服务端session_id、必要时双方录音 | P61: 未执行
A62: E2E-059 | B62: App + MCU + 服务端 | C62: 局域网 | D62: EchoBraid局域网外呼需要用户批准 | E62: P1 | F62: iOS/Android | G62: App + MCU + 服务端 | H62: 三端真机人工 | I62: 手机与EchoBraid同局域网，自动允许关闭且已配对 | J62: 合法测试号码与任务 | K62: 桌面下发dial；在手机先拒绝，再重新下发并批准 | L62: 拒绝不拨号；批准后创建一次本地任务；来源可识别 | M62: 仅批准后收到dial | N62: 云端只用于实际通话；LAN控制不经过云端 | O62: App日志+截图、MCU日志、服务端session_id、必要时双方录音 | P62: 未执行
A63: E2E-060 | B63: App + MCU + 服务端 | C63: 局域网 | D63: 自动允许局域网呼叫时直接入队 | E63: P1 | F63: iOS/Android | G63: App + MCU + 服务端 | H63: 三端真机人工 | I63: LAN已配对且自动允许开启 | J63: 合法测试任务 | K63: 桌面下发一次；观察任务与拨号 | L63: 无需二次确认但只执行一次；设置关闭后下一次恢复询问 | M63: 按任务执行dial | N63: 实时通话仍使用正常鉴权/session | O63: App日志+截图、MCU日志、服务端session_id、必要时双方录音 | P63: 未执行
A64: E2E-061 | B64: App + MCU + 服务端 | C64: 局域网 | D64: 无效LAN token/来源被拒绝 | E64: P0 | F64: iOS/Android | G64: App + MCU + 服务端 | H64: 三端真机人工 | I64: 构造未配对客户端或错误token | J64: 外呼任务含合法号码 | K64: 尝试建立连接并下发dial | L64: 不展示为可信任务且不拨号；记录安全事件但不泄漏详情 | M64: 未收到任何控制命令 | N64: 无实时session | O64: App日志+截图、MCU日志、服务端session_id、必要时双方录音 | P64: 未执行
A65: E2E-062 | B65: App + MCU + 服务端 | C65: 摘要记录 | D65: 三端结束状态与摘要最终一致 | E65: P0 | F65: iOS/Android | G65: App + MCU + 服务端 | H65: 三端真机人工 | I65: 完成包含双方对话的来电与外呼各一通 | J65: 固定号码与脚本 | K65: 结束后等待摘要；对照App、MCU终态和服务端session | L65: 方向、号码、时长、ended_by、转录、摘要一致；无重复记录 | M65: 每通唯一sid并复位idle | N65: 每通唯一session且摘要映射正确 | O65: App日志+截图、MCU日志、服务端session_id、必要时双方录音 | P65: 未执行

Sheet OTA恢复
A1: CallMate / TonoCard 测试用例 · OTA 与恢复
A2: 共 30 条；按优先级、平台、组合层级和执行结果筛选。MCU 日志行首为 32.768 kHz raw tick，重启前后禁止直接相减。
A3: 用例 ID | B3: 一级模块 | C3: 二级模块 | D3: 用例标题 | E3: 优先级 | F3: 平台 | G3: 组合层级 | H3: 自动化建议 | I3: 前置条件 | J3: 测试数据 | K3: 操作步骤 | L3: App 预期结果 | M3: MCU 预期结果 | N3: 服务端预期结果 | O3: 证据/日志 | P3: 执行结果 | Q3: 缺陷 ID | R3: 依据/备注
A4: OTA-001 | B4: OTA 与恢复 | C4: 检查更新 | D4: 当前已是最新版本 | E4: P1 | F4: iOS/Android | G4: App + MCU + OTA服务 | H4: 真机半自动 | I4: MCU连接且OTA服务返回相同版本 | J4: 使用当前测试版本与独立测试账号；执行前清理上一条用例残留状态 | K4: 进入首页/设备页触发检查 | L4: 显示已是最新或不弹升级；不重复提示 | M4: 只响应get_info/fw_slot_info，不进入OTA会话 | N4: latest返回当前版本与正确设备类型 | O4: App OTA日志+截图、MCU日志/slot状态、OTA请求 | P4: 未执行
A5: OTA-002 | B5: OTA 与恢复 | C5: 检查更新 | D5: 发现高版本并显示更新信息 | E5: P0 | F5: iOS/Android | G5: App + MCU + OTA服务 | H5: 真机半自动 | I5: 服务端返回兼容高版本 | J5: 使用当前测试版本与独立测试账号；执行前清理上一条用例残留状态 | K5: 触发检查；查看版本与更新入口 | L5: 显示当前/目标版本和明确操作；不会静默使用错误设备包 | M5: 保持idle等待fw_begin | N5: metadata包含版本、大小、校验与下载地址 | O5: App OTA日志+截图、MCU日志/slot状态、OTA请求 | P5: 未执行
A6: OTA-003 | B6: OTA 与恢复 | C6: 检查更新 | D6: 52J与525包严格匹配 | E6: P0 | F6: iOS/Android | G6: App + MCU + OTA服务 | H6: 真机半自动 | I6: 准备两类板卡与两份固件 | J6: 使用当前测试版本与独立测试账号；执行前清理上一条用例残留状态 | K6: 两块设备分别检查更新并抓取URL | L6: 每块只选择自身deviceName包；无法识别时阻止升级 | M6: 不会接收不匹配板型的升级流程 | N6: 按device参数返回对应明文发布包 | O6: App OTA日志+截图、MCU日志/slot状态、OTA请求 | P6: 未执行
A7: OTA-004 | B7: OTA 与恢复 | C7: 下载 | D7: 固件下载进度与完成校验 | E7: P1 | F7: iOS/Android | G7: App + MCU + OTA服务 | H7: 真机半自动 | I7: 有可用更新且网络正常 | J7: 使用当前测试版本与独立测试账号；执行前清理上一条用例残留状态 | K7: 开始更新；观察下载0-100%；完成后检查进入传输 | L7: 进度单调且不超过100%；下载完成后校验通过才发fw_begin | M7: 下载阶段仍idle | N7: 静态文件长度/哈希与metadata一致 | O7: App OTA日志+截图、MCU日志/slot状态、OTA请求 | P7: 未执行
A8: OTA-005 | B8: OTA 与恢复 | C8: 下载 | D8: 下载中断后可重试 | E8: P1 | F8: iOS/Android | G8: App + MCU + OTA服务 | H8: 真机半自动 | I8: 下载进行到30% | J8: 使用当前测试版本与独立测试账号；执行前清理上一条用例残留状态 | K8: 断网10秒；恢复并重试 | L8: 显示失败/重试；不把残缺文件发送MCU；重试后完成 | M8: 未进入或安全退出OTA会话 | N8: 支持重新下载；无损坏缓存误命中 | O8: App OTA日志+截图、MCU日志/slot状态、OTA请求 | P8: 未执行
A9: OTA-006 | B9: OTA 与恢复 | C9: 开始 | D9: 空闲状态fw_begin成功 | E9: P0 | F9: iOS/Android | G9: App + MCU + OTA服务 | H9: 真机半自动 | I9: 设备空闲、slot信息正常、固件校验完成 | J9: 使用当前测试版本与独立测试账号；执行前清理上一条用例残留状态 | K9: 发fw_begin并观察UI/MCU状态 | L9: 进入升级中并阻止重复开始；显示传输阶段 | M9: 锁定OTA owner、进入DOWNLOADING并准备Download区 | N9: 下载服务无额外会话要求 | O9: App OTA日志+截图、MCU日志/slot状态、OTA请求 | P9: 未执行
A10: OTA-007 | B10: OTA 与恢复 | C10: 开始 | D10: 通话/响铃期fw_begin被拒绝 | E10: P0 | F10: iOS/Android | G10: App + MCU + OTA服务 | H10: 真机半自动 | I10: 设备处于incoming或active | J10: 使用当前测试版本与独立测试账号；执行前清理上一条用例残留状态 | K10: 在设备页尝试开始升级 | L10: 本地优先阻止或识别-32050；不打断电话；提示稍后重试 | M10: 拒绝call_active；通话状态不变 | N10: 不涉及 | O10: App OTA日志+截图、MCU日志/slot状态、OTA请求 | P10: 未执行
A11: OTA-008 | B11: OTA 与恢复 | C11: 传输 | D11: Data 0x31盲发完整固件 | E11: P0 | F11: iOS/Android | G11: App + MCU + OTA服务 | H11: OTA自动化+真机 | I11: fw_begin成功 | J11: 已校验固件包 | K11: 传输全部480B chunks；记录速率与内存 | L11: 不等待逐块ACK；进度按已发送字节合理更新；不占用Ctrl发送大块 | M11: 按index/offset/len/crc写入Download区；不发fw_chunk_ack | N11: 不涉及 | O11: App OTA日志+截图、MCU日志/slot状态、OTA请求 | P11: 未执行
A12: OTA-009 | B12: OTA 与恢复 | C12: 传输 | D12: fw_verify无缺块直接通过 | E12: P0 | F12: iOS/Android | G12: App + MCU + OTA服务 | H12: 真机半自动 | I12: 所有chunks正确到达 | J12: 使用当前测试版本与独立测试账号；执行前清理上一条用例残留状态 | K12: 发送fw_verify | L12: 解析result missing为空并继续fw_end | M12: 校验bitmap/CRC后返回无missing | N12: 不涉及 | O12: App OTA日志+截图、MCU日志/slot状态、OTA请求 | P12: 未执行
A13: OTA-010 | B13: OTA 与恢复 | C13: 传输 | D13: fw_verify返回missing ranges后补传 | E13: P0 | F13: iOS/Android | G13: App + MCU + OTA服务 | H13: OTA自动化+真机 | I13: 故意丢弃多个不连续chunk | J13: 可控丢块 | K13: 发送fw_verify；按ranges补传；再次verify | L13: 只补缺失块；进度不倒退异常；第二次通过 | M13: result携带missing ranges；补齐后校验成功 | N13: 不涉及 | O13: App OTA日志+截图、MCU日志/slot状态、OTA请求 | P13: 未执行
A14: OTA-011 | B14: OTA 与恢复 | C14: 传输 | D14: chunk CRC错误被发现并补传 | E14: P0 | F14: iOS/Android | G14: App + MCU + OTA服务 | H14: 真机半自动 | I14: 篡改一个chunk payload或crc | J14: 使用当前测试版本与独立测试账号；执行前清理上一条用例残留状态 | K14: 发送全部chunks；verify；补传正确块 | L14: 不会进入安装错误镜像；显示正在校验/修复；最终成功 | M14: 错误块不标记有效；missing/verify指示补传 | N14: 不涉及 | O14: App OTA日志+截图、MCU日志/slot状态、OTA请求 | P14: 未执行
A15: OTA-012 | B15: OTA 与恢复 | C15: 传输 | D15: 同版本冗余升级返回明确错误 | E15: P1 | F15: iOS/Android | G15: App + MCU + OTA服务 | H15: 真机半自动 | I15: App尝试向相同版本执行fw_begin | J15: 使用当前测试版本与独立测试账号；执行前清理上一条用例残留状态 | K15: 开始更新 | L15: 识别-32052并显示无需升级；结束UI状态 | M15: 拒绝同版本冗余且保持idle | N15: 不涉及 | O15: App OTA日志+截图、MCU日志/slot状态、OTA请求 | P15: 未执行
... A33: OTA-030 | B33: OTA 与恢复 | C33: Android恢复 | D33: Android OTA后刷新GATT服务缓存 | E33: P0 | F33: Android | G33: App + MCU + OTA服务 | H33: 真机半自动 | I33: 完成删除/变更GATT服务的v2升级train | J33: 使用当前测试版本与独立测试账号；执行前清理上一条用例残留状态 | K33: 等待重启；App执行post-OTA refresh与重连 | L33: 重新发现Ctrl/Data；不因旧缓存缺特征永久失败；设备页版本更新 | M33: 提供v2 GATT表并接受新attach | N33: 不涉及 | O33: App OTA日志+截图、MCU日志/slot状态、OTA请求 | P33: 未执行

Sheet 异常性能安全
A1: CallMate / TonoCard 测试用例 · 异常、性能与安全
A2: 共 31 条；按优先级、平台、组合层级和执行结果筛选。MCU 日志行首为 32.768 kHz raw tick，重启前后禁止直接相减。
A3: 用例 ID | B3: 一级模块 | C3: 二级模块 | D3: 用例标题 | E3: 优先级 | F3: 平台 | G3: 组合层级 | H3: 自动化建议 | I3: 前置条件 | J3: 测试数据 | K3: 操作步骤 | L3: App 预期结果 | M3: MCU 预期结果 | N3: 服务端预期结果 | O3: 证据/日志 | P3: 执行结果 | Q3: 缺陷 ID | R3: 依据/备注
A4: NFR-001 | B4: 异常、性能与安全 | C4: 性能 | D4: 冷启动到可交互首页时间 | E4: P1 | F4: iOS/Android | G4: 非功能/安全 | H4: 启动性能自动化 | I4: 已完成绑定引导，设备在线和离线各一轮 | J4: 每轮清理后台进程 | K4: 彻底杀进程后启动10次；记录首帧与首页可交互时间 | L4: P50/P95形成版本基线；启动期间无长时间白屏；在线/离线状态准确 | M4: 按用例场景无异常重启、资源泄漏或状态污染 | N4: 按用例场景无幽灵会话、越权或不可回收资源 | O4: 性能数据、系统资源、App/MCU/服务端日志 | P4: 未执行
A5: NFR-002 | B5: 异常、性能与安全 | C5: 性能 | D5: 40条通话列表滚动性能 | E5: P1 | F5: iOS/Android | G5: 非功能/安全 | H5: UI性能自动化 | I5: 注入40条包含摘要的记录 | J5: 固定种子数据 | K5: 连续上滑8次到第15条后；记录耗时、掉帧和内存 | L5: 目标行可见；无明显卡死；滚动测试在项目阈值35秒内完成 | M5: 按用例场景无异常重启、资源泄漏或状态污染 | N5: 按用例场景无幽灵会话、越权或不可回收资源 | O5: 性能数据、系统资源、App/MCU/服务端日志 | P5: 未执行
A6: NFR-003 | B6: 异常、性能与安全 | C6: 性能 | D6: 1000条通话记录分页与搜索 | E6: P2 | F6: iOS/Android | G6: 非功能/安全 | H6: 专项人工/自动化 | I6: 准备1000条混合记录 | J6: 使用当前测试版本与独立测试账号；执行前清理上一条用例残留状态 | K6: 启动首页；分页到底部若干页；搜索/筛选常见号码 | L6: 首屏不一次加载全部；内存可控；结果无重复漏项；操作可取消 | M6: 按用例场景无异常重启、资源泄漏或状态污染 | N6: 按用例场景无幽灵会话、越权或不可回收资源 | O6: 性能数据、系统资源、App/MCU/服务端日志 | P6: 未执行
A7: NFR-004 | B7: 异常、性能与安全 | C7: 性能 | D7: AI分身长对话分页 | E7: P2 | F7: iOS/Android | G7: 非功能/安全 | H7: 专项人工/自动化 | I7: 准备500条历史消息 | J7: 使用当前测试版本与独立测试账号；执行前清理上一条用例残留状态 | K7: 打开AI分身；快速向上加载历史；发送新消息 | L7: 首屏快速可用；历史按页加载且顺序正确；新消息不跳错位置 | M7: 按用例场景无异常重启、资源泄漏或状态污染 | N7: 按用例场景无幽灵会话、越权或不可回收资源 | O7: 性能数据、系统资源、App/MCU/服务端日志 | P7: 未执行
A8: NFR-005 | B8: 异常、性能与安全 | C8: 性能 | D8: 连续50通后的内存与线程稳定 | E8: P0 | F8: iOS/Android | G8: 非功能/安全 | H8: 双机测试台 | I8: 双机测试台可执行短通话 | J8: 50轮固定语料 | K8: 交替执行50通并采集每5通资源 | L8: 内存/线程/队列无单调不可回收增长；第50通双向音频仍正常 | M8: 按用例场景无异常重启、资源泄漏或状态污染 | N8: 按用例场景无幽灵会话、越权或不可回收资源 | O8: 性能数据、系统资源、App/MCU/服务端日志 | P8: 未执行
A9: NFR-006 | B9: 异常、性能与安全 | C9: 长稳 | D9: App前后台24小时重连稳定 | E9: P1 | F9: iOS/Android | G9: 非功能/安全 | H9: 专项人工/自动化 | I9: 设备保持供电，手机正常网络 | J9: 24小时 | K9: App后台24小时；期间让设备离开/回到范围3次；次日打开 | L9: 最终能自动恢复；无重复授权、幽灵连接和异常耗电峰值 | M9: 按用例场景无异常重启、资源泄漏或状态污染 | N9: 按用例场景无幽灵会话、越权或不可回收资源 | O9: 性能数据、系统资源、App/MCU/服务端日志 | P9: 未执行
A10: NFR-007 | B10: 异常、性能与安全 | C10: 长稳 | D10: MCU空闲72小时后首通可用 | E10: P1 | F10: iOS/Android | G10: 非功能/安全 | H10: 专项人工/自动化 | I10: 设备与App绑定并进入低功耗空闲 | J10: 72小时 | K10: 保持72小时；发起第一通陌生来电 | L10: 唤醒、连接、代接与双向音频一次成功；无必须重启蓝牙现象 | M10: 按用例场景无异常重启、资源泄漏或状态污染 | N10: 按用例场景无幽灵会话、越权或不可回收资源 | O10: 性能数据、系统资源、App/MCU/服务端日志 | P10: 未执行
